Workbook

Sheet Risk Dashboard
A1: TATA MOTORS — RISK MANAGEMENT & SENSITIVITY DASHBOARD
A2: Task: Risk Management and Sensitivity Analysis in Financial Decision-Making | FY2025-26
A4: EXECUTIVE RISK SCORECARD
A5: FY26A Revenue | B5: FY26A EBITDA | C5: Selected Scenario | D5: Scenario DCF / Share | E5: Base WACC | F5: Interest Shock | G5: Capex / Revenue | H5: Top Risk | I5: Reference Price | J5: DCF vs Ref. | K5: Priority | L5: Posture
A6: ='Risk Inputs'!B4 -> 83855 | B6: ='Risk Inputs'!B5 -> 10314 | C6: ='Scenario Manager'!B11 -> Base | D6: ='DCF Stress Test'!B27 -> 239.508 | E6: ='Risk Inputs'!B26 -> 0.11 | F6: ='Scenario Manager'!B19 -> 0 | G6: ='Scenario Manager'!B18 -> 0.035 | H6: Revenue / demand | I6: ='Risk Inputs'!B27 -> 874 | J6: ='DCF Stress Test'!B27/'Risk Inputs'!B27-1 -> -0.72596338 | K6: 1 | L6: =IF(J6<0,"Cautious","Monitor") -> Cautious
A9: SCENARIO OUTCOMES | H9: RISK DRIVER MAP
A10: Scenario | B10: Revenue FY31E | C10: UFCF FY31E | D10: DCF / Share | E10: Vs Ref. | F10: Interpretation | H10: Driver | I10: Base | J10: Stress range | K10: Impact | L10: Control
A11: Downside | B11: ='Risk Inputs'!B4*(1+'Scenario Manager'!B4)^5 -> 102022.43 | C11: =(((('Risk Inputs'!$B$4*(1+'Scenario Manager'!B4)^5)*'Scenario Manager'!B5)-(('Risk Inputs'!$B$4*(1+'Scenario Manager'!B4)^5)*'Risk Inputs'!$B$22))*(1-'Risk Inputs'!$B$21))+(('Risk Inputs'!$B$4*(1+'Scenario Manager'!B4)^5)*'Risk Inputs'!$B$22)-(('Risk Inputs'!$B$4*(1+'Scenario Manager'!B4)^5)*'Scenario Manager'!B7)-((('Risk Inputs'!$B$4*(1+'Scenario Manager'!B4)^5)*'Risk Inputs'!$B$24)-(('Risk Inputs'!$B$4*(1+'Scenario Manager'!B4)^4)*'Risk Inputs'!$B$24)) -> 3814.0693 | D11: =(((((((('Risk Inputs'!$B$4*(1+'Scenario Manager'!B4))*'Scenario Manager'!B5)-(('Risk Inputs'!$B$4*(1+'Scenario Manager'!B4))*'Risk Inputs'!$B$22))*(1-'Risk Inputs'!$B$21))+(('Risk Inputs'!$B$4*(1+'Scenario Manager'!B4))*'Risk Inputs'!$B$22)-(('Risk Inputs'!$B$4*(1+'Scenario Manager'!B4))*'Scenario Manager'!B7)-((('Risk Inputs'!$B$4*(1+'Scenario Manager'!B4))*'Risk Inputs'!$B$24)-('Risk Inputs'!$B$4*'Risk Inputs'!$B$24)))/(1+'Scenario Manager'!B6)^1)+((((((('Risk Inputs'!$B$4*(1+'Scenario Manager'!B4))*(1+'Scenario Manager'!B4))*'Scenario Manager'!B5)-((('Risk Inputs'!$B$4*(1+'Scenario Manager'!B4))*(1+'Scenario Manager'!B4))*'Risk Inputs'!$B$22))*(1-'Risk Inputs'!$B$21))+((('Risk Inputs'!$B$4*(1+'Scenario Manager'!B4))*(1+'Scenario Manager'!B4))*'Risk Inputs'!$B$22)-((('Risk Inputs'!$B$4*(1+'Scenario Manager'!B4))*(1+'Scenario Manager'!B4))*'Scenario Manager'!B7)-(((('Risk Inputs'!$B$4*(1+'Scenario Manager'!B4))*(1+'Scenario Manager'!B4))*'Risk Inputs'!$B$24)-(('Risk Inputs'!$B$4*(1+'Scenario Manager'!B4))*'Risk Inputs'!$B$24)))/(1+'Scenario Manager'!B6)^2)+(((((((('Risk Inputs'!$B$4*(1+'Scenario Manager'!B4))*(1+'Scenario Manager'!B4))*(1+'Scenario Manager'!B4))*'Scenario Manager'!B5)-(((('Risk Inputs'!$B$4*(1+'Scenario Manager'!B4))*(1+'Scenario Manager'!B4))*(1+'Scenario Manager'!B4))*'Risk Inputs'!$B$22))*(1-'Risk Inputs'!$B$21))+(((('Risk Inputs'!$B$4*(1+'Scenario Manager'!B4))*(1+'Scenario Manager'!B4))*(1+'Scenario Manager'!B4))*'Risk Inputs'!$B$22)-(((('Risk Inputs'!$B$4*(1+'Scenario Manager'!B4))*(1+'Scenario Manager'!B4))*(1+'Scenario Manager'!B4))*'Scenario Manager'!B7)-((((('Risk Inputs'!$B$4*(1+'Scenario Manager'!B4))*(1+'Scenario Manager'!B4))*(1+'Scenario Manager'!B4))*'Risk Inputs'!$B$24)-((('Risk Inputs'!$B$4*(1+'Scenario Manager'!B4))*(1+'Scenario Manager'!B4))*'Risk Inputs'!$B$24)))/(1+'Scenario Manager'!B6)^3)+((((((((('Risk Inputs'!$B$4*(1+'Scenario Manager'!B4))*(1+'Scenario Manager'!B4))*(1+'Scenario Manager'!B4))*(1+'Scenario Manager'!B4))*'Scenario Manager'!B5)-((((('Risk Inputs'!$B$4*(1+'Scenario Manager'!B4))*(1+'Scenario Manager'!B4))*(1+'Scenario Manager'!B4))*(1+'Scenario Manager'!B4))*'Risk Inputs'!$B$22))*(1-'Risk Inputs'!$B$21))+((((('Risk Inputs'!$B$4*(1+'Scenario Manager'!B4))*(1+'Scenario Manager'!B4))*(1+'Scenario Manager'!B4))*(1+'Scenario Manager'!B4))*'Risk Inputs'!$B$22)-((((('Risk Inputs'!$B$4*(1+'Scenario Manager'!B4))*(1+'Scenario Manager'!B4))*(1+'Scenario Manager'!B4))*(1+'Scenario Manager'!B4))*'Scenario Manager'!B7)-(((((('Risk Inputs'!$B$4*(1+'Scenario Manager'!B4))*(1+'Scenario Manager'!B4))*(1+'Scenario Manager'!B4))*(1+'Scenario Manager'!B4))*'Risk Inputs'!$B$24)-(((('Risk Inputs'!$B$4*(1+'Scenario Manager'!B4))*(1+'Scenario Manager'!B4))*(1+'Scenario Manager'!B4))*'Risk Inputs'!$B$24)))/(1+'Scenario Manager'!B6)^4)+(((((((((('Risk Inputs'!$B$4*(1+'Scenario Manager'!B4))*(1+'Scenario Manager'!B4))*(1+'Scenario Manager'!B4))*(1+'Scenario Manager'!B4))*(1+'Scenario Manager'!B4))*'Scenario Manager'!B5)-(((((('Risk Inputs'!$B$4*(1+'Scenario Manager'!B4))*(1+'Scenario Manager'!B4))*(1+'Scenario Manager'!B4))*(1+'Scenario Manager'!B4))*(1+'Scenario Manager'!B4))*'Risk Inputs'!$B$22))*(1-'Risk Inputs'!$B$21))+(((((('Risk Inputs'!$B$4*(1+'Scenario Manager'!B4))*(1+'Scenario Manager'!B4))*(1+'Scenario Manager'!B4))*(1+'Scenario Manager'!B4))*(1+'Scenario Manager'!B4))*'Risk Inputs'!$B$22)-(((((('Risk Inputs'!$B$4*(1+'Scenario Manager'!B4))*(1+'Scenario Manager'!B4))*(1+'Scenario Manager'!B4))*(1+'Scenario Manager'!B4))*(1+'Scenario Manager'!B4))*'Scenario Manager'!B7)-((((((('Risk Inputs'!$B$4*(1+'Scenario Manager'!B4))*(1+'Scenario Manager'!B4))*(1+'Scenario Manager'!B4))*(1+'Scenario Manager'!B4))*(1+'Scenario Manager'!B4))*'Risk Inputs'!$B$24)-((((('Risk Inputs'!$B$4*(1+'Scenario Manager'!B4))*(1+'Scenario Manager'!B4))*(1+'Scenario Manager'!B4))*(1+'Scenario Manager'!B4))*'Risk Inputs'!$B$24)))/(1+'Scenario Manager'!B6)^5)+((((((((((('Risk Inputs'!$B$4*(1+'Scenario Manager'!B4))*(1+'Scenario Manager'!B4))*(1+'Scenario Manager'!B4))*(1+'Scenario Manager'!B4))*(1+'Scenario Manager'!B4))*'Scenario Manager'!B5)-(((((('Risk Inputs'!$B$4*(1+'Scenario Manager'!B4))*(1+'Scenario Manager'!B4))*(1+'Scenario Manager'!B4))*(1+'Scenario Manager'!B4))*(1+'Scenario Manager'!B4))*'Risk Inputs'!$B$22))*(1-'Risk Inputs'!$B$21))+(((((('Risk Inputs'!$B$4*(1+'Scenario Manager'!B4))*(1+'Scenario Manager'!B4))*(1+'Scenario Manager'!B4))*(1+'Scenario Manager'!B4))*(1+'Scenario Manager'!B4))*'Risk Inputs'!$B$22)-(((((('Risk Inputs'!$B$4*(1+'Scenario Manager'!B4))*(1+'Scenario Manager'!B4))*(1+'Scenario Manager'!B4))*(1+'Scenario Manager'!B4))*(1+'Scenario Manager'!B4))*'Scenario Manager'!B7)-((((((('Risk Inputs'!$B$4*(1+'Scenario Manager'!B4))*(1+'Scenario Manager'!B4))*(1+'Scenario Manager'!B4))*(1+'Scenario Manager'!B4))*(1+'Scenario Manager'!B4))*'Risk Inputs'!$B$24)-((((('Risk Inputs'!$B$4*(1+'Scenario Manager'!B4))*(1+'Scenario Manager'!B4))*(1+'Scenario Manager'!B4))*(1+'Scenario Manager'!B4))*'Risk Inputs'!$B$24)))*(1+'Risk Inputs'!$B$25)/('Scenario Manager'!B6-'Risk Inputs'!$B$25))/(1+'Scenario Manager'!B6)^5))+'Risk Inputs'!$B$13)/'Risk Inputs'!$B$14 -> 104.09609 | E11: =D11/'Risk Inputs'!B27-1 -> -0.88089693 | F11: Capital preservation / high caution | H11: Revenue growth | I11: 7.0% | J11: 4.0%-9.0% | K11: High | L11: Reforecast
A12: Base | B12: ='Risk Inputs'!B4*(1+'Scenario Manager'!C4)^5 -> 117610.98 | C12: =(((('Risk Inputs'!$B$4*(1+'Scenario Manager'!C4)^5)*'Scenario Manager'!C5)-(('Risk Inputs'!$B$4*(1+'Scenario Manager'!C4)^5)*'Risk Inputs'!$B$22))*(1-'Risk Inputs'!$B$21))+(('Risk Inputs'!$B$4*(1+'Scenario Manager'!C4)^5)*'Risk Inputs'!$B$22)-(('Risk Inputs'!$B$4*(1+'Scenario Manager'!C4)^5)*'Scenario Manager'!C7)-((('Risk Inputs'!$B$4*(1+'Scenario Manager'!C4)^5)*'Risk Inputs'!$B$24)-(('Risk Inputs'!$B$4*(1+'Scenario Manager'!C4)^4)*'Risk Inputs'!$B$24)) -> 7162.7282 | D12: =(((((((('Risk Inputs'!$B$4*(1+'Scenario Manager'!C4))*'Scenario Manager'!C5)-(('Risk Inputs'!$B$4*(1+'Scenario Manager'!C4))*'Risk Inputs'!$B$22))*(1-'Risk Inputs'!$B$21))+(('Risk Inputs'!$B$4*(1+'Scenario Manager'!C4))*'Risk Inputs'!$B$22)-(('Risk Inputs'!$B$4*(1+'Scenario Manager'!C4))*'Scenario Manager'!C7)-((('Risk Inputs'!$B$4*(1+'Scenario Manager'!C4))*'Risk Inputs'!$B$24)-('Risk Inputs'!$B$4*'Risk Inputs'!$B$24)))/(1+'Scenario Manager'!C6)^1)+((((((('Risk Inputs'!$B$4*(1+'Scenario Manager'!C4))*(1+'Scenario Manager'!C4))*'Scenario Manager'!C5)-((('Risk Inputs'!$B$4*(1+'Scenario Manager'!C4))*(1+'Scenario Manager'!C4))*'Risk Inputs'!$B$22))*(1-'Risk Inputs'!$B$21))+((('Risk Inputs'!$B$4*(1+'Scenario Manager'!C4))*(1+'Scenario Manager'!C4))*'Risk Inputs'!$B$22)-((('Risk Inputs'!$B$4*(1+'Scenario Manager'!C4))*(1+'Scenario Manager'!C4))*'Scenario Manager'!C7)-(((('Risk Inputs'!$B$4*(1+'Scenario Manager'!C4))*(1+'Scenario Manager'!C4))*'Risk Inputs'!$B$24)-(('Risk Inputs'!$B$4*(1+'Scenario Manager'!C4))*'Risk Inputs'!$B$24)))/(1+'Scenario Manager'!C6)^2)+(((((((('Risk Inputs'!$B$4*(1+'Scenario Manager'!C4))*(1+'Scenario Manager'!C4))*(1+'Scenario Manager'!C4))*'Scenario Manager'!C5)-(((('Risk Inputs'!$B$4*(1+'Scenario Manager'!C4))*(1+'Scenario Manager'!C4))*(1+'Scenario Manager'!C4))*'Risk Inputs'!$B$22))*(1-'Risk Inputs'!$B$21))+(((('Risk Inputs'!$B$4*(1+'Scenario Manager'!C4))*(1+'Scenario Manager'!C4))*(1+'Scenario Manager'!C4))*'Risk Inputs'!$B$22)-(((('Risk Inputs'!$B$4*(1+'Scenario Manager'!C4))*(1+'Scenario Manager'!C4))*(1+'Scenario Manager'!C4))*'Scenario Manager'!C7)-((((('Risk Inputs'!$B$4*(1+'Scenario Manager'!C4))*(1+'Scenario Manager'!C4))*(1+'Scenario Manager'!C4))*'Risk Inputs'!$B$24)-((('Risk Inputs'!$B$4*(1+'Scenario Manager'!C4))*(1+'Scenario Manager'!C4))*'Risk Inputs'!$B$24)))/(1+'Scenario Manager'!C6)^3)+((((((((('Risk Inputs'!$B$4*(1+'Scenario Manager'!C4))*(1+'Scenario Manager'!C4))*(1+'Scenario Manager'!C4))*(1+'Scenario Manager'!C4))*'Scenario Manager'!C5)-((((('Risk Inputs'!$B$4*(1+'Scenario Manager'!C4))*(1+'Scenario Manager'!C4))*(1+'Scenario Manager'!C4))*(1+'Scenario Manager'!C4))*'Risk Inputs'!$B$22))*(1-'Risk Inputs'!$B$21))+((((('Risk Inputs'!$B$4*(1+'Scenario Manager'!C4))*(1+'Scenario Manager'!C4))*(1+'Scenario Manager'!C4))*(1+'Scenario Manager'!C4))*'Risk Inputs'!$B$22)-((((('Risk Inputs'!$B$4*(1+'Scenario Manager'!C4))*(1+'Scenario Manager'!C4))*(1+'Scenario Manager'!C4))*(1+'Scenario Manager'!C4))*'Scenario Manager'!C7)-(((((('Risk Inputs'!$B$4*(1+'Scenario Manager'!C4))*(1+'Scenario Manager'!C4))*(1+'Scenario Manager'!C4))*(1+'Scenario Manager'!C4))*'Risk Inputs'!$B$24)-(((('Risk Inputs'!$B$4*(1+'Scenario Manager'!C4))*(1+'Scenario Manager'!C4))*(1+'Scenario Manager'!C4))*'Risk Inputs'!$B$24)))/(1+'Scenario Manager'!C6)^4)+(((((((((('Risk Inputs'!$B$4*(1+'Scenario Manager'!C4))*(1+'Scenario Manager'!C4))*(1+'Scenario Manager'!C4))*(1+'Scenario Manager'!C4))*(1+'Scenario Manager'!C4))*'Scenario Manager'!C5)-(((((('Risk Inputs'!$B$4*(1+'Scenario Manager'!C4))*(1+'Scenario Manager'!C4))*(1+'Scenario Manager'!C4))*(1+'Scenario Manager'!C4))*(1+'Scenario Manager'!C4))*'Risk Inputs'!$B$22))*(1-'Risk Inputs'!$B$21))+(((((('Risk Inputs'!$B$4*(1+'Scenario Manager'!C4))*(1+'Scenario Manager'!C4))*(1+'Scenario Manager'!C4))*(1+'Scenario Manager'!C4))*(1+'Scenario Manager'!C4))*'Risk Inputs'!$B$22)-(((((('Risk Inputs'!$B$4*(1+'Scenario Manager'!C4))*(1+'Scenario Manager'!C4))*(1+'Scenario Manager'!C4))*(1+'Scenario Manager'!C4))*(1+'Scenario Manager'!C4))*'Scenario Manager'!C7)-((((((('Risk Inputs'!$B$4*(1+'Scenario Manager'!C4))*(1+'Scenario Manager'!C4))*(1+'Scenario Manager'!C4))*(1+'Scenario Manager'!C4))*(1+'Scenario Manager'!C4))*'Risk Inputs'!$B$24)-((((('Risk Inputs'!$B$4*(1+'Scenario Manager'!C4))*(1+'Scenario Manager'!C4))*(1+'Scenario Manager'!C4))*(1+'Scenario Manager'!C4))*'Risk Inputs'!$B$24)))/(1+'Scenario Manager'!C6)^5)+((((((((((('Risk Inputs'!$B$4*(1+'Scenario Manager'!C4))*(1+'Scenario Manager'!C4))*(1+'Scenario Manager'!C4))*(1+'Scenario Manager'!C4))*(1+'Scenario Manager'!C4))*'Scenario Manager'!C5)-(((((('Risk Inputs'!$B$4*(1+'Scenario Manager'!C4))*(1+'Scenario Manager'!C4))*(1+'Scenario Manager'!C4))*(1+'Scenario Manager'!C4))*(1+'Scenario Manager'!C4))*'Risk Inputs'!$B$22))*(1-'Risk Inputs'!$B$21))+(((((('Risk Inputs'!$B$4*(1+'Scenario Manager'!C4))*(1+'Scenario Manager'!C4))*(1+'Scenario Manager'!C4))*(1+'Scenario Manager'!C4))*(1+'Scenario Manager'!C4))*'Risk Inputs'!$B$22)-(((((('Risk Inputs'!$B$4*(1+'Scenario Manager'!C4))*(1+'Scenario Manager'!C4))*(1+'Scenario Manager'!C4))*(1+'Scenario Manager'!C4))*(1+'Scenario Manager'!C4))*'Scenario Manager'!C7)-((((((('Risk Inputs'!$B$4*(1+'Scenario Manager'!C4))*(1+'Scenario Manager'!C4))*(1+'Scenario Manager'!C4))*(1+'Scenario Manager'!C4))*(1+'Scenario Manager'!C4))*'Risk Inputs'!$B$24)-((((('Risk Inputs'!$B$4*(1+'Scenario Manager'!C4))*(1+'Scenario Manager'!C4))*(1+'Scenario Manager'!C4))*(1+'Scenario Manager'!C4))*'Risk Inputs'!$B$24)))*(1+'Risk Inputs'!$B$25)/('Scenario Manager'!C6-'Risk Inputs'!$B$25))/(1+'Scenario Manager'!C6)^5))+'Risk Inputs'!$B$13)/'Risk Inputs'!$B$14 -> 239.508 | E12: =D12/'Risk Inputs'!B27-1 -> -0.72596338 | F12: Balanced monitoring | H12: EBITDA margin | I12: 12.5% | J12: 10.5%-14.5% | K12: High | L12: Hedge + pricing
A13: Upside | B13: ='Risk Inputs'!B4*(1+'Scenario Manager'!D4)^5 -> 129021.31 | C13: =(((('Risk Inputs'!$B$4*(1+'Scenario Manager'!D4)^5)*'Scenario Manager'!D5)-(('Risk Inputs'!$B$4*(1+'Scenario Manager'!D4)^5)*'Risk Inputs'!$B$22))*(1-'Risk Inputs'!$B$21))+(('Risk Inputs'!$B$4*(1+'Scenario Manager'!D4)^5)*'Risk Inputs'!$B$22)-(('Risk Inputs'!$B$4*(1+'Scenario Manager'!D4)^5)*'Scenario Manager'!D7)-((('Risk Inputs'!$B$4*(1+'Scenario Manager'!D4)^5)*'Risk Inputs'!$B$24)-(('Risk Inputs'!$B$4*(1+'Scenario Manager'!D4)^4)*'Risk Inputs'!$B$24)) -> 10961.485 | D13: =(((((((('Risk Inputs'!$B$4*(1+'Scenario Manager'!D4))*'Scenario Manager'!D5)-(('Risk Inputs'!$B$4*(1+'Scenario Manager'!D4))*'Risk Inputs'!$B$22))*(1-'Risk Inputs'!$B$21))+(('Risk Inputs'!$B$4*(1+'Scenario Manager'!D4))*'Risk Inputs'!$B$22)-(('Risk Inputs'!$B$4*(1+'Scenario Manager'!D4))*'Scenario Manager'!D7)-((('Risk Inputs'!$B$4*(1+'Scenario Manager'!D4))*'Risk Inputs'!$B$24)-('Risk Inputs'!$B$4*'Risk Inputs'!$B$24)))/(1+'Scenario Manager'!D6)^1)+((((((('Risk Inputs'!$B$4*(1+'Scenario Manager'!D4))*(1+'Scenario Manager'!D4))*'Scenario Manager'!D5)-((('Risk Inputs'!$B$4*(1+'Scenario Manager'!D4))*(1+'Scenario Manager'!D4))*'Risk Inputs'!$B$22))*(1-'Risk Inputs'!$B$21))+((('Risk Inputs'!$B$4*(1+'Scenario Manager'!D4))*(1+'Scenario Manager'!D4))*'Risk Inputs'!$B$22)-((('Risk Inputs'!$B$4*(1+'Scenario Manager'!D4))*(1+'Scenario Manager'!D4))*'Scenario Manager'!D7)-(((('Risk Inputs'!$B$4*(1+'Scenario Manager'!D4))*(1+'Scenario Manager'!D4))*'Risk Inputs'!$B$24)-(('Risk Inputs'!$B$4*(1+'Scenario Manager'!D4))*'Risk Inputs'!$B$24)))/(1+'Scenario Manager'!D6)^2)+(((((((('Risk Inputs'!$B$4*(1+'Scenario Manager'!D4))*(1+'Scenario Manager'!D4))*(1+'Scenario Manager'!D4))*'Scenario Manager'!D5)-(((('Risk Inputs'!$B$4*(1+'Scenario Manager'!D4))*(1+'Scenario Manager'!D4))*(1+'Scenario Manager'!D4))*'Risk Inputs'!$B$22))*(1-'Risk Inputs'!$B$21))+(((('Risk Inputs'!$B$4*(1+'Scenario Manager'!D4))*(1+'Scenario Manager'!D4))*(1+'Scenario Manager'!D4))*'Risk Inputs'!$B$22)-(((('Risk Inputs'!$B$4*(1+'Scenario Manager'!D4))*(1+'Scenario Manager'!D4))*(1+'Scenario Manager'!D4))*'Scenario Manager'!D7)-((((('Risk Inputs'!$B$4*(1+'Scenario Manager'!D4))*(1+'Scenario Manager'!D4))*(1+'Scenario Manager'!D4))*'Risk Inputs'!$B$24)-((('Risk Inputs'!$B$4*(1+'Scenario Manager'!D4))*(1+'Scenario Manager'!D4))*'Risk Inputs'!$B$24)))/(1+'Scenario Manager'!D6)^3)+((((((((('Risk Inputs'!$B$4*(1+'Scenario Manager'!D4))*(1+'Scenario Manager'!D4))*(1+'Scenario Manager'!D4))*(1+'Scenario Manager'!D4))*'Scenario Manager'!D5)-((((('Risk Inputs'!$B$4*(1+'Scenario Manager'!D4))*(1+'Scenario Manager'!D4))*(1+'Scenario Manager'!D4))*(1+'Scenario Manager'!D4))*'Risk Inputs'!$B$22))*(1-'Risk Inputs'!$B$21))+((((('Risk Inputs'!$B$4*(1+'Scenario Manager'!D4))*(1+'Scenario Manager'!D4))*(1+'Scenario Manager'!D4))*(1+'Scenario Manager'!D4))*'Risk Inputs'!$B$22)-((((('Risk Inputs'!$B$4*(1+'Scenario Manager'!D4))*(1+'Scenario Manager'!D4))*(1+'Scenario Manager'!D4))*(1+'Scenario Manager'!D4))*'Scenario Manager'!D7)-(((((('Risk Inputs'!$B$4*(1+'Scenario Manager'!D4))*(1+'Scenario Manager'!D4))*(1+'Scenario Manager'!D4))*(1+'Scenario Manager'!D4))*'Risk Inputs'!$B$24)-(((('Risk Inputs'!$B$4*(1+'Scenario Manager'!D4))*(1+'Scenario Manager'!D4))*(1+'Scenario Manager'!D4))*'Risk Inputs'!$B$24)))/(1+'Scenario Manager'!D6)^4)+(((((((((('Risk Inputs'!$B$4*(1+'Scenario Manager'!D4))*(1+'Scenario Manager'!D4))*(1+'Scenario Manager'!D4))*(1+'Scenario Manager'!D4))*(1+'Scenario Manager'!D4))*'Scenario Manager'!D5)-(((((('Risk Inputs'!$B$4*(1+'Scenario Manager'!D4))*(1+'Scenario Manager'!D4))*(1+'Scenario Manager'!D4))*(1+'Scenario Manager'!D4))*(1+'Scenario Manager'!D4))*'Risk Inputs'!$B$22))*(1-'Risk Inputs'!$B$21))+(((((('Risk Inputs'!$B$4*(1+'Scenario Manager'!D4))*(1+'Scenario Manager'!D4))*(1+'Scenario Manager'!D4))*(1+'Scenario Manager'!D4))*(1+'Scenario Manager'!D4))*'Risk Inputs'!$B$22)-(((((('Risk Inputs'!$B$4*(1+'Scenario Manager'!D4))*(1+'Scenario Manager'!D4))*(1+'Scenario Manager'!D4))*(1+'Scenario Manager'!D4))*(1+'Scenario Manager'!D4))*'Scenario Manager'!D7)-((((((('Risk Inputs'!$B$4*(1+'Scenario Manager'!D4))*(1+'Scenario Manager'!D4))*(1+'Scenario Manager'!D4))*(1+'Scenario Manager'!D4))*(1+'Scenario Manager'!D4))*'Risk Inputs'!$B$24)-((((('Risk Inputs'!$B$4*(1+'Scenario Manager'!D4))*(1+'Scenario Manager'!D4))*(1+'Scenario Manager'!D4))*(1+'Scenario Manager'!D4))*'Risk Inputs'!$B$24)))/(1+'Scenario Manager'!D6)^5)+((((((((((('Risk Inputs'!$B$4*(1+'Scenario Manager'!D4))*(1+'Scenario Manager'!D4))*(1+'Scenario Manager'!D4))*(1+'Scenario Manager'!D4))*(1+'Scenario Manager'!D4))*'Scenario Manager'!D5)-(((((('Risk Inputs'!$B$4*(1+'Scenario Manager'!D4))*(1+'Scenario Manager'!D4))*(1+'Scenario Manager'!D4))*(1+'Scenario Manager'!D4))*(1+'Scenario Manager'!D4))*'Risk Inputs'!$B$22))*(1-'Risk Inputs'!$B$21))+(((((('Risk Inputs'!$B$4*(1+'Scenario Manager'!D4))*(1+'Scenario Manager'!D4))*(1+'Scenario Manager'!D4))*(1+'Scenario Manager'!D4))*(1+'Scenario Manager'!D4))*'Risk Inputs'!$B$22)-(((((('Risk Inputs'!$B$4*(1+'Scenario Manager'!D4))*(1+'Scenario Manager'!D4))*(1+'Scenario Manager'!D4))*(1+'Scenario Manager'!D4))*(1+'Scenario Manager'!D4))*'Scenario Manager'!D7)-((((((('Risk Inputs'!$B$4*(1+'Scenario Manager'!D4))*(1+'Scenario Manager'!D4))*(1+'Scenario Manager'!D4))*(1+'Scenario Manager'!D4))*(1+'Scenario Manager'!D4))*'Risk Inputs'!$B$24)-((((('Risk Inputs'!$B$4*(1+'Scenario Manager'!D4))*(1+'Scenario Manager'!D4))*(1+'Scenario Manager'!D4))*(1+'Scenario Manager'!D4))*'Risk Inputs'!$B$24)))*(1+'Risk Inputs'!$B$25)/('Scenario Manager'!D6-'Risk Inputs'!$B$25))/(1+'Scenario Manager'!D6)^5))+'Risk Inputs'!$B$13)/'Risk Inputs'!$B$14 -> 505.1269 | E13: =D13/'Risk Inputs'!B27-1 -> -0.42205161 | F13: Execution-led upside case | H13: WACC | I13: 11.0% | J13: 9.0%-13.0% | K13: High | L13: Monitor rates
H14: Interest shock | I14: 0.0% | J14: -2.0% to +2.0% | K14: Medium | L14: Liquidity / hedges
H15: Capex / Revenue | I15: 3.5% | J15: 2.5%-4.5% | K15: Medium | L15: Stage-gate
A18: INVESTMENT-BANKING DECISION FRAMEWORK
A19: Risk management should be embedded in valuation rather than treated as a separate narrative. In this model, revenue growth, EBITDA margin and WACC drive the largest valuation swings; interest-rate shocks flow into financing cost and can also affect the required return; capex intensity changes near-term free cash flow. The recommended process is to refresh the base/downside/upside cases regularly, monitor leading indicators, and require a margin of safety before making capital-allocation decisions.

Sheet Risk Inputs
A1: TATA MOTORS — RISK MANAGEMENT INPUTS
A3: Metric | B3: FY26A | C3: Unit | D3: Source
A4: Revenue from operations | B4: 83855 | C4: ₹ cr | D4: Annual Report FY26
A5: Underlying EBITDA | B5: 10314 | C5: ₹ cr | D5: Annual Report FY26
A6: Underlying EBITDA margin | B6: =B5/B4 -> 0.12299803 | C6: % | D6: Calculated
A7: Underlying EBIT | B7: 8538 | C7: ₹ cr | D7: Annual Report FY26
A8: D&A | B8: 1945 | C8: ₹ cr | D8: Annual Report FY26
A9: Operating cash flow | B9: 14981 | C9: ₹ cr | D9: Annual Report FY26
A10: Free cash flow | B10: 12438 | C10: ₹ cr | D10: Annual Report FY26
A11: Total debt | B11: 4817 | C11: ₹ cr | D11: Annual Report FY26
A12: Cash & equivalents | B12: 6899 | C12: ₹ cr | D12: Annual Report FY26
A13: Net cash (simple bridge) | B13: =B12-B11 -> 2082 | C13: ₹ cr | D13: Cash less debt
A14: Shares outstanding | B14: 368 | C14: Cr shares | D14: Week 3 model
A17: BASE FORECAST ASSUMPTIONS
A18: Input | B18: Base Value | C18: Unit | D18: Use
A19: Revenue growth | B19: 0.07 | C19: % per year | D19: Top-line sensitivity
A20: EBITDA margin | B20: 0.125 | C20: % of revenue | D20: Margin sensitivity
A21: Tax rate | B21: 0.25 | C21: % | D21: DCF tax
A22: D&A / Revenue | B22: 0.023 | C22: % | D22: DCF
A23: Capex / Revenue | B23: 0.035 | C23: % | D23: Capex sensitivity
A24: NWC / Revenue | B24: 0.055 | C24: % | D24: Working capital
A25: Terminal growth | B25: 0.04 | C25: % | D25: Terminal value
A26: WACC | B26: 0.11 | C26: % | D26: Discount rate
A27: Interest expense | B27: 874 | C27: ₹ cr | D27: Financing base
A28: Reference market price | B28: 459.1 | C28: ₹ / share | D28: Week 3 benchmark

Sheet Scenario Manager
A1: SCENARIO MANAGER — RISK CASES
A3: Driver | B3: Downside | C3: Base | D3: Upside | E3: Unit
A4: Revenue growth | B4: 0.04 | C4: 0.07 | D4: 0.09 | E4: %
A5: EBITDA margin | B5: 0.105 | C5: 0.125 | D5: 0.145 | E5: %
A6: WACC | B6: 0.13 | C6: 0.11 | D6: 0.09 | E6: %
A7: Capex / Revenue | B7: 0.045 | C7: 0.035 | D7: 0.025 | E7: %
A8: Interest-rate shock | B8: 0.02 | C8: 0 | D8: -0.01 | E8: %
A11: Selected Scenario | B11: Base
A14: Selected Driver | B14: Value | C14: Unit | D14: Interpretation
A15: Revenue growth | B15: =IF($B$11="Downside",$B$4,IF($B$11="Base",$C$4,$D$4)) -> 0.07 | C15: % | D15: Revenue growth stress lever
A16: EBITDA margin | B16: =IF($B$11="Downside",$B$5,IF($B$11="Base",$C$5,$D$5)) -> 0.125 | C16: % | D16: EBITDA margin stress lever
A17: WACC | B17: =IF($B$11="Downside",$B$6,IF($B$11="Base",$C$6,$D$6)) -> 0.11 | C17: % | D17: WACC stress lever
A18: Capex / Revenue | B18: =IF($B$11="Downside",$B$7,IF($B$11="Base",$C$7,$D$7)) -> 0.035 | C18: % | D18: Capex / Revenue stress lever
A19: Interest-rate shock | B19: =IF($B$11="Downside",$B$8,IF($B$11="Base",$C$8,$D$8)) -> 0 | C19: % | D19: Interest-rate shock stress lever

Sheet Sensitivity Analysis
A1: SENSITIVITY ANALYSIS — KEY DECISION VARIABLES
A2: All sensitivity outputs are formula-driven. Base case is centered; adverse cases move toward lower valuation outcomes.
A4: REVENUE GROWTH × WACC | H4: EBITDA MARGIN × WACC
A5: WACC \ Growth | B5: 0.04 | C5: 0.055 | D5: 0.07 | E5: 0.085 | F5: 0.1 | H5: WACC \ Margin | I5: 0.105 | J5: 0.115 | K5: 0.125 | L5: 0.135 | M5: 0.145
