Workbook

Sheet Cover
A1: TATA MOTORS — FINANCIAL MODELING / M&A
A6: Model Purpose | B6: Three-statement forecast + M&A / financing scenario model | D6: Model note: FY26 historical inputs are taken from the uploaded Tata Motors FY2025-26 Integrated Annual Report. Iveco operating assumptions beyond disclosed revenue and purchase consideration are explicit model assumptions and are separated from source-derived data.
A7: Company | B7: Tata Motors Limited (Commercial Vehicles)
A8: Base Period | B8: FY26A (year ended March 31, 2026)
A9: Forecast Period | B9: FY27E–FY31E
A10: Transaction | B10: Proposed acquisition of Iveco Group N.V. (excluding Defence business)
A11: Model Units | B11: ₹ crore, except % / multiples
A12: Primary Source | B12: Tata Motors Integrated Annual Report FY2025-26

Sheet Assumptions
A1: ASSUMPTIONS & SCENARIO CONTROL PANEL
A3: Operating assumptions | B3: Base Case | C3: Downside | D3: Upside | E3: Selected | F3: Units | G3: Source / Note | H3: Input Type | J3: Scenario Selector
A4: Revenue growth | B4: 0.07 | C4: 0.03 | D4: 0.1 | E4: =IF($K$4="Base",B4,IF($K$4="Downside",C4,D4)) -> 0.07 | F4: % | G4: Model assumption based on FY26 performance / outlook | H4: Assumption | J4: Active scenario | K4: Base
A5: EBITDA margin | B5: 0.125 | C5: 0.115 | D5: 0.13 | E5: =IF($K$4="Base",B5,IF($K$4="Downside",C5,D5)) -> 0.125 | F5: % | G5: Base anchored near disclosed 12.3% FY26 underlying EBITDA margin | H5: Source + assumption
A6: Tax rate | B6: 0.25 | C6: 0.25 | D6: 0.25 | E6: =IF($K$4="Base",B6,IF($K$4="Downside",C6,D6)) -> 0.25 | F6: % | G6: Model assumption | H6: Assumption
A7: D&A / Revenue | B7: 0.023 | C7: 0.024 | D7: 0.022 | E7: =IF($K$4="Base",B7,IF($K$4="Downside",C7,D7)) -> 0.023 | F7: % | G7: Approx. FY26 D&A / revenue; forward assumption | H7: Source + assumption
A8: Capex / Revenue | B8: 0.035 | C8: 0.04 | D8: 0.032 | E8: =IF($K$4="Base",B8,IF($K$4="Downside",C8,D8)) -> 0.035 | F8: % | G8: Model assumption | H8: Assumption
A9: NWC as % Revenue | B9: 0.055 | C9: 0.065 | D9: 0.045 | E9: =IF($K$4="Base",B9,IF($K$4="Downside",C9,D9)) -> 0.055 | F9: % | G9: Simplified operating working-capital driver | H9: Assumption
A10: Dividend payout | B10: 0.2 | C10: 0.1 | D10: 0.25 | E10: =IF($K$4="Base",B10,IF($K$4="Downside",C10,D10)) -> 0.2 | F10: % | G10: Model assumption; FY26 Board recommended ₹4/share | H10: Source + assumption
A11: Minimum cash | B11: 4000 | C11: 4000 | D11: 5000 | E11: =IF($K$4="Base",B11,IF($K$4="Downside",C11,D11)) -> 4000 | F11: ₹ crore | G11: Liquidity floor — model assumption | H11: Assumption
A12: Intangible additions / Revenue | B12: 0.005 | C12: 0.005 | D12: 0.005 | E12: 0.005 | F12: % | G12: Model assumption for simplified forecast | H12: Assumption
A14: M&A / Iveco assumptions | B14: Base Case | C14: Downside | D14: Upside | E14: Selected | F14: Units | G14: Source / Note | H14: Input Type
A15: Iveco FY25 revenue | B15: 134000 | C15: 125000 | D15: 145000 | E15: =IF($K$16="Base",B15,IF($K$16="Downside",C15,D15)) -> 134000 | F15: ₹ crore | G15: Tata Motors disclosed 2025 Iveco revenue of €13.4bn; ₹/€ conversion is a modeling assumption | H15: Source + assumption | J15: M&A scenario selector
A16: Iveco revenue growth | B16: 0.03 | C16: 0 | D16: 0.06 | E16: =IF($K$16="Base",B16,IF($K$16="Downside",C16,D16)) -> 0.03 | F16: % | G16: Model assumption | H16: Assumption | J16: Active M&A scenario | K16: Base
A17: Iveco EBITDA margin | B17: 0.08 | C17: 0.06 | D17: 0.1 | E17: =IF($K$16="Base",B17,IF($K$16="Downside",C17,D17)) -> 0.08 | F17: % | G17: Model assumption (not disclosed in uploaded file) | H17: Assumption
A18: Iveco D&A / Revenue | B18: 0.03 | C18: 0.035 | D18: 0.028 | E18: =IF($K$16="Base",B18,IF($K$16="Downside",C18,D18)) -> 0.03 | F18: % | G18: Model assumption | H18: Assumption
A19: Iveco tax rate | B19: 0.25 | C19: 0.27 | D19: 0.23 | E19: =IF($K$16="Base",B19,IF($K$16="Downside",C19,D19)) -> 0.25 | F19: % | G19: Model assumption | H19: Assumption
A20: Iveco capex / Revenue | B20: 0.03 | C20: 0.035 | D20: 0.028 | E20: =IF($K$16="Base",B20,IF($K$16="Downside",C20,D20)) -> 0.03 | F20: % | G20: Model assumption | H20: Assumption
A21: FY27 contribution factor | B21: 0.75 | C21: 0.5 | D21: 0.75 | E21: =IF($K$16="Base",B21,IF($K$16="Downside",C21,D21)) -> 0.75 | F21: % | G21: Deal expected to complete in Q2 FY27; contribution factor is a modeling assumption | H21: Source + assumption
A22: Annual synergy run-rate | B22: 1500 | C22: 750 | D22: 2000 | E22: =IF($K$16="Base",B22,IF($K$16="Downside",C22,D22)) -> 1500 | F22: ₹ crore | G22: Model assumption for procurement / overhead synergies | H22: Assumption
A23: Synergy ramp FY27 | B23: 0.25 | C23: 0.2 | D23: 0.3 | E23: =IF($K$16="Base",B23,IF($K$16="Downside",C23,D23)) -> 0.25 | F23: % | G23: Model assumption | H23: Assumption
A24: Synergy ramp FY28 | B24: 0.5 | C24: 0.4 | D24: 0.6 | E24: =IF($K$16="Base",B24,IF($K$16="Downside",C24,D24)) -> 0.5 | F24: % | G24: Model assumption | H24: Assumption
A25: Synergy ramp FY29 | B25: 0.75 | C25: 0.65 | D25: 0.85 | E25: =IF($K$16="Base",B25,IF($K$16="Downside",C25,D25)) -> 0.75 | F25: % | G25: Model assumption | H25: Assumption
A26: Synergy ramp FY30+ | B26: 1 | C26: 0.9 | D26: 1 | E26: =IF($K$16="Base",B26,IF($K$16="Downside",C26,D26)) -> 1 | F26: % | G26: Model assumption | H26: Assumption
A27: Integration costs FY27 | B27: 250 | C27: 350 | D27: 200 | E27: =IF($K$16="Base",B27,IF($K$16="Downside",C27,D27)) -> 250 | F27: ₹ crore | G27: One-time integration assumption | H27: Assumption
A28: Integration costs FY28 | B28: 100 | C28: 150 | D28: 50 | E28: =IF($K$16="Base",B28,IF($K$16="Downside",C28,D28)) -> 100 | F28: ₹ crore | G28: One-time integration assumption | H28: Assumption
A29: Purchase consideration | B29: 41691 | C29: 41691 | D29: 41691 | E29: =IF($K$16="Base",B29,IF($K$16="Downside",C29,D29)) -> 41691 | F29: ₹ crore | G29: Approx. ₹41,691 cr / €3.8bn excluding Defence | H29: Source-derived
A32: Financing scenarios | B32: Cash % | C32: Debt % | D32: Equity % | E32: Interest Rate | F32: Debt Paydown / Yr | G32: Use Case | H32: Notes | J32: Financing selector
A33: All Cash | B33: 1 | C33: 0 | D33: 0 | E33: 0.075 | F33: 0.2 | G33: Maximum liquidity draw / minimum leverage | H33: Purchase funded from cash | J33: Active financing scenario | K33: Balanced
A34: Balanced | B34: 0.1 | C34: 0.8 | D34: 0.1 | E34: 0.075 | F34: 0.25 | G34: Base financing | H34: Debt-funded with modest equity support
A35: Debt Heavy | B35: 0.05 | C35: 0.9 | D35: 0.05 | E35: 0.08 | F35: 0.2 | G35: Higher leverage / preserve cash | H35: Highest leverage case

Sheet Historical
A1: HISTORICAL FINANCIALS — TATA MOTORS (₹ crore)
A3: Income Statement | B3: FY25 | C3: FY26A | D3: Source
A4: Revenue from operations | B4: 58217 | C4: 83855 | D4: Tata Motors FY26 Annual Report
A5: Other income | B5: 877 | C5: 1124 | D5: Tata Motors FY26 Annual Report
A6: Total income | B6: 59094 | C6: 84979 | D6: Tata Motors FY26 Annual Report
A7: Cost of materials consumed | B7: 31167 | C7: 48840 | D7: Tata Motors FY26 Annual Report
A8: Purchase of products for sale | B8: 6014 | C8: 8184 | D8: Tata Motors FY26 Annual Report
A9: Changes in inventories | B9: 2015 | C9: -292 | D9: Tata Motors FY26 Annual Report
A10: Employee benefits expense | B10: 4223 | C10: 5804 | D10: Tata Motors FY26 Annual Report
A11: Finance costs | B11: 1079 | C11: 874 | D11: Tata Motors FY26 Annual Report
A12: Foreign exchange (gain)/loss | B12: 91 | C12: -100 | D12: Tata Motors FY26 Annual Report
A13: D&A expense | B13: 1690 | C13: 1945 | D13: Tata Motors FY26 Annual Report
A14: Product development/engineering expense | B14: 814 | C14: 789 | D14: Tata Motors FY26 Annual Report
A15: Other expenses | B15: 8672 | C15: 11689 | D15: Tata Motors FY26 Annual Report
... A24: Profit after tax | B24: 3195 | C24: 3030 | D24: Tata Motors FY26 Annual Report
A27: Balance Sheet | B27: FY25 | C27: FY26A | D27: Source
A28: PP&E | B28: 10886 | C28: 11036 | D28: Tata Motors FY26 Annual Report
A29: Capital work-in-progress | B29: 719 | C29: 712 | D29: Tata Motors FY26 Annual Report
A30: Right-of-use assets | B30: 799 | C30: 812 | D30: Tata Motors FY26 Annual Report
A31: Intangible assets + development | B31: 3135 | C31: 3428 | D31: Tata Motors FY26 Annual Report
A32: Equity-accounted investees | B32: 1272 | C32: 1462 | D32: Tata Motors FY26 Annual Report
A33: Non-current investments | B33: 974 | C33: 6547 | D33: Tata Motors FY26 Annual Report
A34: Non-current loans | B34: 25 | C34: 28 | D34: Tata Motors FY26 Annual Report
A35: Other non-current financial assets | B35: 4424 | C35: 4389 | D35: Tata Motors FY26 Annual Report
A36: Non-current tax assets | B36: 329 | C36: 235 | D36: Tata Motors FY26 Annual Report
A37: Other non-current assets | B37: 318 | C37: 451 | D37: Tata Motors FY26 Annual Report
A38: Inventories | B38: 4625 | C38: 5448 | D38: Tata Motors FY26 Annual Report
A39: Current investments | B39: 3036 | C39: 5274 | D39: Tata Motors FY26 Annual Report
... A52: Current tax liabilities | B52: 26 | C52: 59 | D52: Tata Motors FY26 Annual Report
A55: Cash Flow | B55: FY25 (9m) | C55: FY26A | D55: Source
A56: Profit for the year | B56: 3195 | C56: 3030 | D56: Tata Motors FY26 Annual Report
A57: D&A | B57: 1690 | C57: 1945 | D57: Tata Motors FY26 Annual Report
A58: Working capital changes | B58: 1838 | C58: 6657 | D58: Tata Motors FY26 Annual Report
A59: Direct taxes paid | B59: -20 | C59: -942 | D59: Tata Motors FY26 Annual Report
A60: Net cash from operating activities | B60: 8547 | C60: 14981 | D60: Tata Motors FY26 Annual Report
A61: Payments for PP&E & intangibles, net | B61: -1542 | C61: -2103 | D61: Tata Motors FY26 Annual Report
A62: Net cash from investing activities | B62: -3884 | C62: -3451 | D62: Tata Motors FY26 Annual Report
A63: Net borrowings | B63: -6964 | C63: -4339 | D63: Tata Motors FY26 Annual Report
A64: Interest paid | B64: -1006 | C64: -884 | D64: Tata Motors FY26 Annual Report
A65: Net cash from financing activities | B65: -7970 | C65: -5223 | D65: Tata Motors FY26 Annual Report
...

Sheet Forecast IS
A1: FORECAST INCOME STATEMENT — TATA MOTORS + IVECO + SYNERGIES (₹ crore)
A3: Line item | B3: FY26A | C3: FY27E | D3: FY28E | E3: FY29E | F3: FY30E | G3: FY31E
A4: Tata Motors revenue | B4: =Historical!C4 -> 83855 | C4: =Historical!C4*(1+Assumptions!E4) -> 89724.85 | D4: =C4*(1+Assumptions!E4) -> 96005.59 | E4: =D4*(1+Assumptions!E4) -> 102725.98 | F4: =E4*(1+Assumptions!E4) -> 109916.8 | G4: =F4*(1+Assumptions!E4) -> 117610.98
A5: Growth % | D5: =C4/B4-1 -> 0.07 | E5: =D4/C4-1 -> 0.07 | F5: =E4/D4-1 -> 0.07 | G5: =F4/E4-1 -> 0.07
A6: Iveco revenue contribution | B6: =0 -> 0 | C6: ='M&A Model'!C11 -> 103515 | D6: ='M&A Model'!D11 -> 142160.6 | E6: ='M&A Model'!E11 -> 146425.42 | F6: ='M&A Model'!F11 -> 150818.18 | G6: ='M&A Model'!G11 -> 155342.73
A7: Total revenue | B7: =SUM(B4,B6) -> 83855 | C7: =SUM(C4,C6) -> 193239.85 | D7: =SUM(D4,D6) -> 238166.19 | E7: =SUM(E4,E6) -> 249151.4 | F7: =SUM(F4,F6) -> 260734.98 | G7: =SUM(G4,G6) -> 272953.7
A8: EBITDA — Tata Motors | B8: =Historical!C4*12.3% -> 10314.165 | C8: =C4*Assumptions!E5 -> 11215.606 | D8: =D4*Assumptions!E5 -> 12000.699 | E8: =E4*Assumptions!E5 -> 12840.748 | F8: =F4*Assumptions!E5 -> 13739.6 | G8: =G4*Assumptions!E5 -> 14701.372
A9: EBITDA — Iveco | B9: =0 -> 0 | C9: ='M&A Model'!C12 -> 8281.2 | D9: ='M&A Model'!D12 -> 11372.848 | E9: ='M&A Model'!E12 -> 11714.033 | F9: ='M&A Model'!F12 -> 12065.454 | G9: ='M&A Model'!G12 -> 12427.418
A10: EBITDA — synergies | B10: =0 -> 0 | C10: ='M&A Model'!C15 -> 375 | D10: ='M&A Model'!D15 -> 750 | E10: ='M&A Model'!E15 -> 1125 | F10: ='M&A Model'!F15 -> 1500 | G10: ='M&A Model'!G15 -> 1500
A11: Total EBITDA | B11: =SUM(B8:B10) -> 10314.165 | C11: =SUM(C8:C10) -> 19871.806 | D11: =SUM(D8:D10) -> 24123.547 | E11: =SUM(E8:E10) -> 25679.781 | F11: =SUM(F8:F10) -> 27305.054 | G11: =SUM(G8:G10) -> 28628.79
A12: EBITDA margin | B12: =B11/B7 -> 0.123 | C12: =C11/C7 -> 0.10283493 | D12: =D11/D7 -> 0.10128871 | E12: =E11/E7 -> 0.10306898 | F12: =F11/F7 -> 0.1047234 | G12: =G11/G7 -> 0.10488515
A13: D&A — Tata Motors | B13: =Historical!C13 -> 1945 | C13: =C4*Assumptions!E7 -> 2063.6716 | D13: =D4*Assumptions!E7 -> 2208.1286 | E13: =E4*Assumptions!E7 -> 2362.6976 | F13: =F4*Assumptions!E7 -> 2528.0864 | G13: =G4*Assumptions!E7 -> 2705.0524
A14: D&A — Iveco | B14: =0 -> 0 | C14: ='M&A Model'!C13 -> 3105.45 | D14: ='M&A Model'!D13 -> 4264.818 | E14: ='M&A Model'!E13 -> 4392.7625 | F14: ='M&A Model'!F13 -> 4524.5454 | G14: ='M&A Model'!G13 -> 4660.2818
A15: Total D&A | B15: =SUM(B13:B14) -> 1945 | C15: =SUM(C13:C14) -> 5169.1215 | D15: =SUM(D13:D14) -> 6472.9466 | E15: =SUM(E13:E14) -> 6755.4601 | F15: =SUM(F13:F14) -> 7052.6318 | G15: =SUM(G13:G14) -> 7365.3342
A16: EBIT | B16: =B11-B15 -> 8369.165 | C16: =C11-C15 -> 14702.685 | D16: =D11-D15 -> 17650.6 | E16: =E11-E15 -> 18924.321 | F16: =F11-F15 -> 20252.423 | G16: =G11-G15 -> 21263.456
A17: Finance costs | B17: =Historical!C11 -> 874 | C17: =Historical!C11+'M&A Model'!C10 -> 3375.46 | D17: =Historical!C11+'M&A Model'!D10 -> 2750.095 | E17: =Historical!C11+'M&A Model'!E10 -> 2281.0712 | F17: =Historical!C11+'M&A Model'!F10 -> 1929.3034 | G17: =Historical!C11+'M&A Model'!G10 -> 1665.4776
A18: Other income | B18: =Historical!C5 -> 1124 | C18: =Historical!C5 -> 1124 | D18: =Historical!C5 -> 1124 | E18: =Historical!C5 -> 1124 | F18: =Historical!C5 -> 1124 | G18: =Historical!C5 -> 1124
A19: Integration costs | B19: =Historical!C21 -> 1428 | C19: ='M&A Model'!C16 -> 250 | D19: ='M&A Model'!D16 -> 100 | E19: ='M&A Model'!E16 -> 0 | F19: ='M&A Model'!F16 -> 0 | G19: ='M&A Model'!G16 -> 0
A20: Pre-tax income | B20: =Historical!C22 -> 4663 | C20: =C16-C17+C18-C19 -> 12201.225 | D20: =D16-D17+D18-D19 -> 15924.505 | E20: =E16-E17+E18-E19 -> 17767.25 | F20: =F16-F17+F18-F19 -> 19447.119 | G20: =G16-G17+G18-G19 -> 20721.978
A21: Tax | B21: =Historical!C23 -> 1633 | C21: =C20*Assumptions!E6 -> 3050.3062 | D21: =D20*Assumptions!E6 -> 3981.1263 | E21: =E20*Assumptions!E6 -> 4441.8124 | F21: =F20*Assumptions!E6 -> 4861.7798 | G21: =G20*Assumptions!E6 -> 5180.4946
A22: Net income | B22: =Historical!C24 -> 3030 | C22: =C20-C21 -> 9150.9185 | D22: =D20-D21 -> 11943.379 | E22: =E20-E21 -> 13325.437 | F22: =F20-F21 -> 14585.339 | G22: =G20-G21 -> 15541.484
A23: Net margin | B23: =B22/B7 -> 0.036133802 | C23: =C22/C7 -> 0.047355235 | D23: =D22/D7 -> 0.050147247 | E23: =E22/E7 -> 0.053483293 | F23: =F22/F7 -> 0.055939327 | G23: =G22/G7 -> 0.056938168

Sheet Forecast BS
A1: FORECAST BALANCE SHEET — SIMPLIFIED DRIVER MODEL
A3: ₹ crore | B3: FY26A | C3: FY27E | D3: FY28E | E3: FY29E | F3: FY30E | G3: FY31E
A4: PP&E + CWIP + ROU | B4: =Historical!C28+Historical!C29+Historical!C30 -> 12560 | C4: =B4-'Forecast IS'!C15+(-'Forecast CF'!C9) -> 14154.273 | D4: =C4-'Forecast IS'!D15+(-'Forecast CF'!D9) -> 16017.143 | E4: =D4-'Forecast IS'!E15+(-'Forecast CF'!E9) -> 17981.982 | F4: =E4-'Forecast IS'!F15+(-'Forecast CF'!F9) -> 20055.075 | G4: =F4-'Forecast IS'!G15+(-'Forecast CF'!G9) -> 22243.12
A5: Intangible assets | B5: =Historical!C31 -> 3428 | C5: =B5+'Forecast IS'!C7*Assumptions!E12 -> 4394.1992 | D5: =C5+'Forecast IS'!D7*Assumptions!E12 -> 5585.0302 | E5: =D5+'Forecast IS'!E7*Assumptions!E12 -> 6830.7872 | F5: =E5+'Forecast IS'!F7*Assumptions!E12 -> 8134.4621 | G5: =F5+'Forecast IS'!G7*Assumptions!E12 -> 9499.2306
A6: Other non-current assets | B6: =Historical!C32+Historical!C33+Historical!C34+Historical!C35+Historical!C36+Historical!C37 -> 13112 | C6: =B6 -> 13112 | D6: =B6 -> 13112 | E6: =B6 -> 13112 | F6: =B6 -> 13112 | G6: =B6 -> 13112
A7: Inventory | B7: =Historical!C38 -> 5448 | C7: =B7+'Forecast IS'!C7*Assumptions!E9 -> 16076.192 | D7: =C7+'Forecast IS'!D7*Assumptions!E9 -> 29175.332 | E7: =D7+'Forecast IS'!E7*Assumptions!E9 -> 42878.659 | F7: =E7+'Forecast IS'!F7*Assumptions!E9 -> 57219.083 | G7: =F7+'Forecast IS'!G7*Assumptions!E9 -> 72231.537
A8: Trade receivables | B8: =Historical!C40 -> 2721 | C8: =B8/'Forecast IS'!B7*'Forecast IS'!C7 -> 6270.4148 | D8: =B8/'Forecast IS'!B7*'Forecast IS'!D7 -> 7728.2237 | E8: =B8/'Forecast IS'!B7*'Forecast IS'!E7 -> 8084.6814 | F8: =B8/'Forecast IS'!B7*'Forecast IS'!F7 -> 8460.5555 | G8: =B8/'Forecast IS'!B7*'Forecast IS'!G7 -> 8857.0392
A9: Cash & equivalents | B9: =Historical!C41 -> 6899 | C9: ='Forecast CF'!C19 -> -4423.2901 | D9: ='Forecast CF'!D19 -> -11606.693 | E9: ='Forecast CF'!E19 -> -18021.58 | F9: ='Forecast CF'!F19 -> -23822.128 | G9: ='Forecast CF'!G19 -> -29380.918
A10: Other current / financial assets | B10: =Historical!C39+Historical!C42+Historical!C43 -> 8126 | C10: =B10/'Forecast IS'!B7*'Forecast IS'!C7 -> 18725.98 | D10: =B10/'Forecast IS'!B7*'Forecast IS'!D7 -> 23079.583 | E10: =B10/'Forecast IS'!B7*'Forecast IS'!E7 -> 24144.109 | F10: =B10/'Forecast IS'!B7*'Forecast IS'!F7 -> 25266.62 | G10: =B10/'Forecast IS'!B7*'Forecast IS'!G7 -> 26450.68
A11: Current tax assets + held-for-sale | B11: =15 -> 15 | C11: =B11 -> 15 | D11: =B11 -> 15 | E11: =B11 -> 15 | F11: =B11 -> 15 | G11: =B11 -> 15
A12: Purchase accounting / goodwill | B12: =0 -> 0 | C12: =Assumptions!E29 -> 41691 | D12: =0 -> 0 | E12: =0 -> 0 | F12: =0 -> 0 | G12: =0 -> 0
A13: Total assets | B13: =SUM(B4:B12) -> 52309 | C13: =SUM(C4:C12) -> 110015.77 | D13: =SUM(D4:D12) -> 83105.62 | E13: =SUM(E4:E12) -> 95025.639 | F13: =SUM(F4:F12) -> 108440.67 | G13: =SUM(G4:G12) -> 123027.69
A14: Debt | B14: =Historical!C46 -> 4817 | C14: =Historical!C46+'M&A Model'!C8 -> 38169.8 | D14: =Historical!C46+'M&A Model'!D8 -> 29831.6 | E14: =Historical!C46+'M&A Model'!E8 -> 23577.95 | F14: =Historical!C46+'M&A Model'!F8 -> 18887.713 | G14: =Historical!C46+'M&A Model'!G8 -> 15370.034
A15: Lease liabilities | B15: =Historical!C47 -> 798 | C15: =B15 -> 798 | D15: =C15 -> 798 | E15: =D15 -> 798 | F15: =E15 -> 798 | G15: =F15 -> 798
A16: Trade payables | B16: =Historical!C48 -> 15704 | C16: ='Forecast IS'!C7*(Historical!C48/Historical!C4) -> 36189.119 | D16: ='Forecast IS'!D7*(Historical!C48/Historical!C4) -> 44602.729 | E16: ='Forecast IS'!E7*(Historical!C48/Historical!C4) -> 46659.991 | F16: ='Forecast IS'!F7*(Historical!C48/Historical!C4) -> 48829.314 | G16: ='Forecast IS'!G7*(Historical!C48/Historical!C4) -> 51117.583
A17: Other liabilities / (assets) — balancing plug | B17: =B13-B14-B15-B16-B19 -> 18256 | C17: =C13-C14-C15-C16-C19 -> 10635.014 | D17: =D13-D14-D15-D16-D19 -> -25905.247 | E17: =E13-E14-E15-E16-E19 -> -20449.19 | F17: =F13-F14-F15-F16-F19 -> -16181.518 | G17: =G13-G14-G15-G16-G19 -> -12798.275
A18: Total liabilities | B18: =SUM(B14:B17) -> 39575 | C18: =SUM(C14:C17) -> 85791.934 | D18: =SUM(D14:D17) -> 49327.082 | E18: =SUM(E14:E17) -> 50586.751 | F18: =SUM(F14:F17) -> 52333.508 | G18: =SUM(G14:G17) -> 54487.343
A19: Equity | B19: =Historical!C45 -> 12734 | C19: =B19+'Forecast IS'!C22+'Forecast CF'!C15+'M&A Model'!C7 -> 24223.835 | D19: =C19+'Forecast IS'!D22+'Forecast CF'!D15 -> 33778.538 | E19: =D19+'Forecast IS'!E22+'Forecast CF'!E15 -> 44438.888 | F19: =E19+'Forecast IS'!F22+'Forecast CF'!F15 -> 56107.159 | G19: =F19+'Forecast IS'!G22+'Forecast CF'!G15 -> 68540.346
A20: Balance check | B20: =B13-B18-B19 -> 0 | C20: =C13-C18-C19 -> 0 | D20: =D13-D18-D19 -> 0 | E20: =E13-E18-E19 -> 0 | F20: =F13-F18-F19 -> 0 | G20: =G13-G18-G19 -> 0
A21: Model note
A22: Model note
A23: Balance-sheet methodology | B23: Driver-based pro forma. Non-core assets and liabilities are simplified; the balancing line isolates the unforecast portion of the balance sheet.
A24: Limitation | B24: This is not a purchase-price-allocation / diligence-grade balance sheet. Replace simplified drivers with PPA, tax, working-capital and debt schedules when diligence data are available.

Sheet Forecast CF
A1: FORECAST CASH FLOW STATEMENT — CONSOLIDATED (₹ crore)
A3: Line item | B3: FY26A | C3: FY27E | D3: FY28E | E3: FY29E | F3: FY30E | G3: FY31E
A4: Net income | B4: =Historical!C56 -> 3030 | C4: ='Forecast IS'!C22 -> 9150.9185 | D4: ='Forecast IS'!D22 -> 11943.379 | E4: ='Forecast IS'!E22 -> 13325.437 | F4: ='Forecast IS'!F22 -> 14585.339 | G4: ='Forecast IS'!G22 -> 15541.484
A5: D&A | B5: =Historical!C57 -> 1945 | C5: ='Forecast IS'!C15 -> 5169.1215 | D5: ='Forecast IS'!D15 -> 6472.9466 | E5: ='Forecast IS'!E15 -> 6755.4601 | F5: ='Forecast IS'!F15 -> 7052.6318 | G5: ='Forecast IS'!G15 -> 7365.3342
A6: Change in NWC | B6: =0 -> 0 | C6: ='Forecast BS'!B7-'Forecast BS'!C7 -> -10628.192 | D6: ='Forecast BS'!C7-'Forecast BS'!D7 -> -13099.14 | E6: ='Forecast BS'!D7-'Forecast BS'!E7 -> -13703.327 | F6: ='Forecast BS'!E7-'Forecast BS'!F7 -> -14340.424 | G6: ='Forecast BS'!F7-'Forecast BS'!G7 -> -15012.454
A7: Other non-cash / integration | B7: =0 -> 0 | C7: =ABS('M&A Model'!C16) -> 250 | D7: =ABS('M&A Model'!D16) -> 100 | E7: =0 -> 0 | F7: =0 -> 0 | G7: =0 -> 0
A8: Cash flow from operations | B8: =Historical!C60 -> 14981 | C8: =SUM(C4:C7) -> 3941.8483 | D8: =SUM(D4:D7) -> 5417.185 | E8: =SUM(E4:E7) -> 6377.5704 | F8: =SUM(F4:F7) -> 7297.5473 | G8: =SUM(G4:G7) -> 7894.3643
A9: Capex | B9: =Historical!C61 -> -2103 | C9: =-'Forecast IS'!C7*Assumptions!E8 -> -6763.3948 | D9: =-'Forecast IS'!D7*Assumptions!E8 -> -8335.8166 | E9: =-'Forecast IS'!E7*Assumptions!E8 -> -8720.299 | F9: =-'Forecast IS'!F7*Assumptions!E8 -> -9125.7243 | G9: =-'Forecast IS'!G7*Assumptions!E8 -> -9553.3795
A10: Acquisition consideration | B10: =0 -> 0 | C10: =-'M&A Model'!C4 -> -41691 | D10: =0 -> 0 | E10: =0 -> 0 | F10: =0 -> 0 | G10: =0 -> 0
A11: Cash flow from investing | B11: =Historical!C62 -> -3451 | C11: =SUM(C9:C10) -> -48454.395 | D11: =SUM(D9:D10) -> -8335.8166 | E11: =SUM(E9:E10) -> -8720.299 | F11: =SUM(F9:F10) -> -9125.7243 | G11: =SUM(G9:G10) -> -9553.3795
A12: Debt funding | B12: =0 -> 0 | C12: ='M&A Model'!C6 -> 33352.8 | D12: =0 -> 0 | E12: =0 -> 0 | F12: =0 -> 0 | G12: =0 -> 0
A13: Equity funding | B13: =0 -> 0 | C13: ='M&A Model'!C7 -> 4169.1 | D13: =0 -> 0 | E13: =0 -> 0 | F13: =0 -> 0 | G13: =0 -> 0
A14: Debt repayment | B14: =Historical!C64 -> -884 | C14: =-'M&A Model'!C10 -> -2501.46 | D14: =-'M&A Model'!D10 -> -1876.095 | E14: =-'M&A Model'!E10 -> -1407.0712 | F14: =-'M&A Model'!F10 -> -1055.3034 | G14: =-'M&A Model'!G10 -> -791.47758
A15: Dividends | B15: =0 -> 0 | C15: =-'Forecast IS'!C22*Assumptions!E10 -> -1830.1837 | D15: =-'Forecast IS'!D22*Assumptions!E10 -> -2388.6758 | E15: =-'Forecast IS'!E22*Assumptions!E10 -> -2665.0875 | F15: =-'Forecast IS'!F22*Assumptions!E10 -> -2917.0679 | G15: =-'Forecast IS'!G22*Assumptions!E10 -> -3108.2967
A16: Cash flow from financing | B16: =Historical!C65 -> -5223 | C16: =SUM(C12:C15) -> 33190.256 | D16: =SUM(D12:D15) -> -4264.7708 | E16: =SUM(E12:E15) -> -4072.1587 | F16: =SUM(F12:F15) -> -3972.3713 | G16: =SUM(G12:G15) -> -3899.7743
A17: Net change in cash | B17: =Historical!C66 -> 6307 | C17: =SUM(C8,C11,C16) -> -11322.29 | D17: =SUM(D8,D11,D16) -> -7183.4024 | E17: =SUM(E8,E11,E16) -> -6414.8872 | F17: =SUM(F8,F11,F16) -> -5800.5484 | G17: =SUM(G8,G11,G16) -> -5558.7896
A18: Beginning cash | B18: =Historical!C41 -> 6899 | C18: =B19 -> 6899 | D18: =C19 -> -4423.2901 | E18: =D19 -> -11606.693 | F18: =E19 -> -18021.58 | G18: =F19 -> -23822.128
A19: Ending cash | B19: =Historical!C41 -> 6899 | C19: =C18+C17 -> -4423.2901 | D19: =D18+D17 -> -11606.693 | E19: =E18+E17 -> -18021.58 | F19: =F18+F17 -> -23822.128 | G19: =G18+G17 -> -29380.918
A20: Free cash flow | B20: =Historical!C67 -> 12438 | C20: =C8+C9 -> -2821.5464 | D20: =D8+D9 -> -2918.6316 | E20: =E8+E9 -> -2342.7285 | F20: =F8+F9 -> -1828.177 | G20: =G8+G9 -> -1659.0153

Sheet M&A Model
A1: M&A / IVECO ACQUISITION MODEL & FINANCING
A3: ₹ crore | B3: FY26A | C3: FY27E | D3: FY28E | E3: FY29E | F3: FY30E | G3: FY31E
A4: Acquisition consideration | B4: =0 -> 0 | C4: =Assumptions!E29 -> 41691 | D4: =0 -> 0 | E4: =0 -> 0 | F4: =0 -> 0 | G4: =0 -> 0
A5: Cash funding | B5: =0 -> 0 | C5: =Assumptions!E29*Assumptions!B34 -> 4169.1 | D5: =0 -> 0 | E5: =0 -> 0 | F5: =0 -> 0 | G5: =0 -> 0
A6: Debt funding | B6: =0 -> 0 | C6: =Assumptions!E29*Assumptions!C34 -> 33352.8 | D6: =0 -> 0 | E6: =0 -> 0 | F6: =0 -> 0 | G6: =0 -> 0
A7: Equity funding | B7: =0 -> 0 | C7: =Assumptions!E29*Assumptions!D34 -> 4169.1 | D7: =0 -> 0 | E7: =0 -> 0 | F7: =0 -> 0 | G7: =0 -> 0
A8: M&A debt balance | B8: =0 -> 0 | C8: =C6 -> 33352.8 | D8: =C8*(1-Assumptions!F34) -> 25014.6 | E8: =D8*(1-Assumptions!F34) -> 18760.95 | F8: =E8*(1-Assumptions!F34) -> 14070.713 | G8: =F8*(1-Assumptions!F34) -> 10553.034
A9: Interest rate | B9: =0 -> 0 | C9: =Assumptions!E34 -> 0.075 | D9: =Assumptions!E34 -> 0.075 | E9: =Assumptions!E34 -> 0.075 | F9: =Assumptions!E34 -> 0.075 | G9: =Assumptions!E34 -> 0.075
A10: Interest expense | B10: =0 -> 0 | C10: =C8*C9 -> 2501.46 | D10: =D8*D9 -> 1876.095 | E10: =E8*E9 -> 1407.0712 | F10: =F8*F9 -> 1055.3034 | G10: =G8*G9 -> 791.47758
A11: Iveco revenue contribution | B11: =0 -> 0 | C11: =Assumptions!E15*(1+Assumptions!E16)*Assumptions!E21 -> 103515 | D11: =Assumptions!E15*(1+Assumptions!E16)^2 -> 142160.6 | E11: =Assumptions!E15*(1+Assumptions!E16)^3 -> 146425.42 | F11: =Assumptions!E15*(1+Assumptions!E16)^4 -> 150818.18 | G11: =Assumptions!E15*(1+Assumptions!E16)^5 -> 155342.73
A12: Iveco EBITDA | B12: =0 -> 0 | C12: =C11*Assumptions!E17 -> 8281.2 | D12: =D11*Assumptions!E17 -> 11372.848 | E12: =E11*Assumptions!E17 -> 11714.033 | F12: =F11*Assumptions!E17 -> 12065.454 | G12: =G11*Assumptions!E17 -> 12427.418
A13: Iveco D&A | B13: =0 -> 0 | C13: =C11*Assumptions!E18 -> 3105.45 | D13: =D11*Assumptions!E18 -> 4264.818 | E13: =E11*Assumptions!E18 -> 4392.7625 | F13: =F11*Assumptions!E18 -> 4524.5454 | G13: =G11*Assumptions!E18 -> 4660.2818
A14: Iveco EBIT | B14: =0 -> 0 | C14: =C12-C13 -> 5175.75 | D14: =D12-D13 -> 7108.03 | E14: =E12-E13 -> 7321.2709 | F14: =F12-F13 -> 7540.909 | G14: =G12-G13 -> 7767.1363
A15: Synergies | B15: =0 -> 0 | C15: =Assumptions!E22*Assumptions!E23 -> 375 | D15: =Assumptions!E22*Assumptions!E24 -> 750 | E15: =Assumptions!E22*Assumptions!E25 -> 1125 | F15: =Assumptions!E22*Assumptions!E26 -> 1500 | G15: =Assumptions!E22*Assumptions!E26 -> 1500
A16: Integration costs | B16: =0 -> 0 | C16: =Assumptions!E27 -> 250 | D16: =Assumptions!E28 -> 100 | E16: =0 -> 0 | F16: =0 -> 0 | G16: =0 -> 0
A17: Net M&A pre-tax profit impact | B17: =0 -> 0 | C17: =C14+C15-C16-C10 -> 2799.29 | D17: =D14+D15-D16-D10 -> 5881.935 | E17: =E14+E15-E16-E10 -> 7039.1997 | F17: =F14+F15-F16-F10 -> 7985.6056 | G17: =G14+G15-G16-G10 -> 8475.6587
A18: Purchase accounting / goodwill | B18: =0 -> 0 | C18: =Assumptions!E29 -> 41691 | D18: =0 -> 0 | E18: =0 -> 0 | F18: =0 -> 0 | G18: =0 -> 0
A19: Acquisition cash outflow | B19: =0 -> 0 | C19: =-C4 -> -41691 | D19: =0 -> 0 | E19: =0 -> 0 | F19: =0 -> 0 | G19: =0 -> 0
A20: Net financing inflow | B20: =0 -> 0 | C20: =C5+C6+C7-C4 -> 0 | D20: =0 -> 0 | E20: =0 -> 0 | F20: =0 -> 0 | G20: =0 -> 0
A21: Minimum cash threshold | B21: =Assumptions!E11 -> 4000 | C21: =Assumptions!E11 -> 4000 | D21: =Assumptions!E11 -> 4000 | E21: =Assumptions!E11 -> 4000 | F21: =Assumptions!E11 -> 4000 | G21: =Assumptions!E11 -> 4000
A22: Funding gap to minimum cash | B22: =0 -> 0 | C22: =MAX(0,Assumptions!E11-'Forecast CF'!C19) -> 8423.2901 | D22: =MAX(0,Assumptions!E11-'Forecast CF'!D19) -> 15606.693 | E22: =MAX(0,Assumptions!E11-'Forecast CF'!E19) -> 22021.58 | F22: =MAX(0,Assumptions!E11-'Forecast CF'!F19) -> 27822.128 | G22: =MAX(0,Assumptions!E11-'Forecast CF'!G19) -> 33380.918

Sheet Dashboard
A1: TATA MOTORS — FINANCIAL MODEL DASHBOARD
A3: KPI | B3: FY26A | C3: FY27E | D3: FY28E | E3: FY29E | F3: FY30E | G3: FY31E | H3: Trend / Note | J3: Selected operating scenario | K3: =Assumptions!K4 -> Base
A4: Revenue (₹ cr) | B4: ='Forecast IS'!B7 -> 83855 | C4: ='Forecast IS'!C7 -> 193239.85 | D4: ='Forecast IS'!D7 -> 238166.19 | E4: ='Forecast IS'!E7 -> 249151.4 | F4: ='Forecast IS'!F7 -> 260734.98 | G4: ='Forecast IS'!G7 -> 272953.7 | H4: FY26 actual → scenario-driven forecast | J4: Selected M&A scenario | K4: =Assumptions!K16 -> Base
A5: EBITDA (₹ cr) | B5: ='Forecast IS'!B11 -> 10314.165 | C5: ='Forecast IS'!C11 -> 19871.806 | D5: ='Forecast IS'!D11 -> 24123.547 | E5: ='Forecast IS'!E11 -> 25679.781 | F5: ='Forecast IS'!F11 -> 27305.054 | G5: ='Forecast IS'!G11 -> 28628.79 | H5: Revenue × selected margin + Iveco + synergies | J5: Selected financing scenario | K5: =Assumptions!K33 -> Balanced
A6: EBITDA margin | B6: ='Forecast IS'!B12 -> 0.123 | C6: ='Forecast IS'!C12 -> 0.10283493 | D6: ='Forecast IS'!D12 -> 0.10128871 | E6: ='Forecast IS'!E12 -> 0.10306898 | F6: ='Forecast IS'!F12 -> 0.1047234 | G6: ='Forecast IS'!G12 -> 0.10488515 | H6: Selected operating scenario | J6: FY27E balance check | K6: ='Forecast BS'!C20 -> 0
A7: Net income (₹ cr) | B7: ='Forecast IS'!B22 -> 3030 | C7: ='Forecast IS'!C22 -> 9150.9185 | D7: ='Forecast IS'!D22 -> 11943.379 | E7: ='Forecast IS'!E22 -> 13325.437 | F7: ='Forecast IS'!F22 -> 14585.339 | G7: ='Forecast IS'!G22 -> 15541.484 | H7: After tax, incl. modeled M&A impact
A8: Free cash flow (₹ cr) | B8: ='Forecast CF'!B20 -> 12438 | C8: ='Forecast CF'!C20 -> -2821.5464 | D8: ='Forecast CF'!D20 -> -2918.6316 | E8: ='Forecast CF'!E20 -> -2342.7285 | F8: ='Forecast CF'!F20 -> -1828.177 | G8: ='Forecast CF'!G20 -> -1659.0153 | H8: CFO less capex
A9: Ending cash (₹ cr) | B9: ='Forecast CF'!B19 -> 6899 | C9: ='Forecast CF'!C19 -> -4423.2901 | D9: ='Forecast CF'!D19 -> -11606.693 | E9: ='Forecast CF'!E19 -> -18021.58 | F9: ='Forecast CF'!F19 -> -23822.128 | G9: ='Forecast CF'!G19 -> -29380.918 | H9: Post-transaction liquidity
A10: Debt (₹ cr) | B10: ='Forecast BS'!B14 -> 4817 | C10: ='Forecast BS'!C14 -> 38169.8 | D10: ='Forecast BS'!D14 -> 29831.6 | E10: ='Forecast BS'!E14 -> 23577.95 | F10: ='Forecast BS'!F14 -> 18887.713 | G10: ='Forecast BS'!G14 -> 15370.034 | H10: Includes acquisition debt / modeled paydown
A12: CONCRETE EVIDENCE / MODEL NOTES
A13: FY26 Revenue | B13: ₹83,855 cr | C13: Source-derived | D13: Annual report p.267
A14: FY26 CFO | B14: ₹14,981 cr | C14: Source-derived | D14: Annual report p.268
A15: FY26 FCF | B15: ₹12,438 cr | C15: Source-derived | D15: Annual report p.269
A16: Iveco Purchase Price | B16: ₹41,691 cr | C16: Source-derived | D16: Annual report p.117
A18: DETAILED VISUAL ANALYSIS
A20: Metric | B20: FY26A | C20: FY27E | D20: FY28E | E20: FY29E | F20: FY30E | G20: FY31E
A21: Revenue | B21: ='Forecast IS'!B7 -> 83855 | C21: ='Forecast IS'!C7 -> 193239.85 | D21: ='Forecast IS'!D7 -> 238166.19 | E21: ='Forecast IS'!E7 -> 249151.4 | F21: ='Forecast IS'!F7 -> 260734.98 | G21: ='Forecast IS'!G7 -> 272953.7
A22: EBITDA | B22: ='Forecast IS'!B11 -> 10314.165 | C22: ='Forecast IS'!C11 -> 19871.806 | D22: ='Forecast IS'!D11 -> 24123.547 | E22: ='Forecast IS'!E11 -> 25679.781 | F22: ='Forecast IS'!F11 -> 27305.054 | G22: ='Forecast IS'!G11 -> 28628.79
A23: Net income | B23: ='Forecast IS'!B22 -> 3030 | C23: ='Forecast IS'!C22 -> 9150.9185 | D23: ='Forecast IS'!D22 -> 11943.379 | E23: ='Forecast IS'!E22 -> 13325.437 | F23: ='Forecast IS'!F22 -> 14585.339 | G23: ='Forecast IS'!G22 -> 15541.484
A24: Ending cash | B24: ='Forecast CF'!B19 -> 6899 | C24: ='Forecast CF'!C19 -> -4423.2901 | D24: ='Forecast CF'!D19 -> -11606.693 | E24: ='Forecast CF'!E19 -> -18021.58 | F24: ='Forecast CF'!F19 -> -23822.128 | G24: ='Forecast CF'!G19 -> -29380.918
A27: M&A contribution bridge | B27: FY27E | C27: FY28E | D27: FY29E | E27: FY30E | F27: FY31E
A28: Iveco EBIT | B28: ='M&A Model'!C14 -> 5175.75 | C28: ='M&A Model'!D14 -> 7108.03 | D28: ='M&A Model'!E14 -> 7321.2709 | E28: ='M&A Model'!F14 -> 7540.909 | F28: ='M&A Model'!G14 -> 7767.1363
A29: Synergies | B29: ='M&A Model'!C15 -> 375 | C29: ='M&A Model'!D15 -> 750 | D29: ='M&A Model'!E15 -> 1125 | E29: ='M&A Model'!F15 -> 1500 | F29: ='M&A Model'!G15 -> 1500
A30: Integration costs | B30: ='M&A Model'!C16 -> 250 | C30: ='M&A Model'!D16 -> 100 | D30: ='M&A Model'!E16 -> 0 | E30: ='M&A Model'!F16 -> 0 | F30: ='M&A Model'!G16 -> 0
A31: Interest expense | B31: ='M&A Model'!C10 -> 2501.46 | C31: ='M&A Model'!D10 -> 1876.095 | D31: ='M&A Model'!E10 -> 1407.0712 | E31: ='M&A Model'!F10 -> 1055.3034 | F31: ='M&A Model'!G10 -> 791.47758
A52: OPERATING SCENARIO EVIDENCE — TATA MOTORS STANDALONE (FY31) | I52: LIQUIDITY WATCH — BALANCED FINANCING CASE
A54: Scenario | B54: Revenue Growth | C54: EBITDA Margin | D54: FY31 Revenue (₹ cr) | E54: FY31 EBITDA (₹ cr) | I54: Metric | J54: Value
A55: Downside | B55: 0.03 | C55: 0.115 | D55: =Historical!C4*(1+B55)^5 -> 97210.928 | E55: =D55*C55 -> 11179.257 | I55: FY27 ending cash | J55: ='Forecast CF'!C19 -> -4423.2901
A56: Base | B56: 0.07 | C56: 0.125 | D56: =Historical!C4*(1+B56)^5 -> 117610.98 | E56: =D56*C56 -> 14701.372 | I56: Minimum cash threshold | J56: =Assumptions!E11 -> 4000
A57: Upside | B57: 0.1 | C57: 0.13 | D57: =Historical!C4*(1+B57)^5 -> 135049.32 | E57: =D57*C57 -> 17556.411 | I57: Funding gap / (surplus) | J57: ='M&A Model'!C22 -> 8423.2901

Sheet Sources
A1: SOURCE REGISTER
A3: Tata Motors | B3: Integrated Annual Report FY2025-26 | C3: Consolidated balance sheet, p. 266 | D3: https://cv.tatamotors.com/annual-reports
A4: Tata Motors | B4: Integrated Annual Report FY2025-26 | C4: Consolidated P&L, p. 267 | D4: https://cv.tatamotors.com/annual-reports
A5: Tata Motors | B5: Integrated Annual Report FY2025-26 | C5: Consolidated cash flow, pp. 268–269 | D5: https://cv.tatamotors.com/annual-reports
A6: Tata Motors | B6: Integrated Annual Report FY2025-26 | C6: FY26 highlights / MDA | D6: Revenue ₹83,855 cr; EBITDA margin 12.3%; FCF ₹12,438 cr
A7: Tata Motors | B7: Integrated Annual Report FY2025-26 | C7: Board’s Report — Iveco | D7: Purchase consideration approx. ₹41,691 cr / €3.8bn excluding Defence; expected completion Q2 FY27
A8: Tata Motors | B8: Integrated Annual Report FY2025-26 | C8: Chairman’s Message — Iveco | D8: 2025 Iveco revenue approx. €13.4bn; annual sales ~140,000 vehicles
A9: Model | B9: Investment banking modeling assumptions | C9: Assumptions sheet | D9: Forward Iveco margins, growth, synergies, integration costs, financing and FX are explicitly modeled assumptions where not disclosed

Sheet Raw Data
A1: RAW DATA — TATA MOTORS FY2025-26 CONSOLIDATED (₹ crore)
A3: Income Statement | B3: FY25 | C3: FY26A | D3: Source / Page | E3: Source Type | F3: Model Use
A4: Revenue from operations | B4: 58217 | C4: 83855 | D4: Tata Motors FY26 Annual Report p.267 | E4: Source-derived | F4: Historical / forecast base
A5: Other income | B5: 877 | C5: 1124 | D5: Tata Motors FY26 Annual Report p.267 | E5: Source-derived | F5: Historical / forecast
A6: Total income | B6: 59094 | C6: 84979 | D6: Tata Motors FY26 Annual Report p.267 | E6: Source-derived | F6: Historical
A7: Cost of materials consumed | B7: 31167 | C7: 48840 | D7: Tata Motors FY26 Annual Report p.267 | E7: Source-derived | F7: Historical
A8: Purchase of products for sale | B8: 6014 | C8: 8184 | D8: Tata Motors FY26 Annual Report p.267 | E8: Source-derived | F8: Historical
A9: Changes in inventories | B9: 2015 | C9: -292 | D9: Tata Motors FY26 Annual Report p.267 | E9: Source-derived | F9: Historical
A10: Employee benefits expense | B10: 4223 | C10: 5804 | D10: Tata Motors FY26 Annual Report p.267 | E10: Source-derived | F10: Historical
A11: Finance costs | B11: 1079 | C11: 874 | D11: Tata Motors FY26 Annual Report p.267 | E11: Source-derived | F11: Historical
A12: Foreign exchange (gain)/loss | B12: 91 | C12: -100 | D12: Tata Motors FY26 Annual Report p.267 | E12: Source-derived | F12: Historical
A13: Depreciation & amortisation | B13: 1690 | C13: 1945 | D13: Tata Motors FY26 Annual Report p.267 | E13: Source-derived | F13: Historical / D&A driver
A14: Product development / engineering | B14: 814 | C14: 789 | D14: Tata Motors FY26 Annual Report p.267 | E14: Source-derived | F14: Historical
A15: Other expenses | B15: 8672 | C15: 11689 | D15: Tata Motors FY26 Annual Report p.267 | E15: Source-derived | F15: Historical
... A24: Profit after tax | B24: 3195 | C24: 3030 | D24: Tata Motors FY26 Annual Report p.267 | E24: Source-derived | F24: Historical / base NI
A27: Balance Sheet | B27: FY25 | C27: FY26A | D27: Source / Page | E27: Source Type | F27: Model Use
A28: Property, plant & equipment | B28: 10886 | C28: 11036 | D28: Tata Motors FY26 Annual Report p.266 | E28: Source-derived | F28: PP&E build
A29: Capital work-in-progress | B29: 719 | C29: 712 | D29: Tata Motors FY26 Annual Report p.266 | E29: Source-derived | F29: Capex base
A30: Right-of-use assets | B30: 799 | C30: 812 | D30: Tata Motors FY26 Annual Report p.266 | E30: Source-derived | F30: Lease / asset base
A31: Other intangible assets | B31: 1979 | C31: 2114 | D31: Tata Motors FY26 Annual Report p.266 | E31: Source-derived | F31: Intangible base
A32: Intangible assets under development | B32: 1156 | C32: 1314 | D32: Tata Motors FY26 Annual Report p.266 | E32: Source-derived | F32: Intangible / R&D
A33: Investment in equity-accounted investees | B33: 1272 | C33: 1462 | D33: Tata Motors FY26 Annual Report p.266 | E33: Source-derived | F33: Non-current investment
A34: Non-current investments | B34: 974 | C34: 6547 | D34: Tata Motors FY26 Annual Report p.266 | E34: Source-derived | F34: Investment balance
A35: Non-current loans | B35: 25 | C35: 28 | D35: Tata Motors FY26 Annual Report p.266 | E35: Source-derived | F35: Financial assets
A36: Other non-current financial assets | B36: 4424 | C36: 4389 | D36: Tata Motors FY26 Annual Report p.266 | E36: Source-derived | F36: Financial assets
A37: Non-current tax assets | B37: 329 | C37: 235 | D37: Tata Motors FY26 Annual Report p.266 | E37: Source-derived | F37: Tax assets
A38: Other non-current assets | B38: 318 | C38: 451 | D38: Tata Motors FY26 Annual Report p.266 | E38: Source-derived | F38: Other assets
A39: Inventories | B39: 4625 | C39: 5448 | D39: Tata Motors FY26 Annual Report p.266 | E39: Source-derived | F39: Working capital
... A55: Current tax liabilities | B55: 26 | C55: 59 | D55: Tata Motors FY26 Annual Report p.267 | E55: Source-derived | F55: Tax / liability
A58: Cash Flow Statement | B58: FY25 (9m) | C58: FY26A | D58: Source / Page | E58: Source Type | F58: Model Use
A59: Profit for the year | B59: 3195 | C59: 3030 | D59: Tata Motors FY26 Annual Report p.268 | E59: Source-derived | F59: Cash flow starting point
A60: D&A | B60: 1690 | C60: 1945 | D60: Tata Motors FY26 Annual Report p.268 | E60: Source-derived | F60: Non-cash add-back
A61: Working capital changes | B61: 1838 | C61: 6657 | D61: Tata Motors FY26 Annual Report p.268 | E61: Source-derived | F61: Cash generation
A62: Direct taxes paid | B62: -20 | C62: -942 | D62: Tata Motors FY26 Annual Report p.268 | E62: Source-derived | F62: Cash tax
A63: Net cash from operating activities | B63: 8547 | C63: 14981 | D63: Tata Motors FY26 Annual Report p.268 | E63: Source-derived | F63: CFO / FCF
A64: Payments for PP&E & intangibles, net | B64: -1542 | C64: -2103 | D64: Tata Motors FY26 Annual Report p.268 | E64: Source-derived | F64: Capex
A65: Net cash from investing activities | B65: -3884 | C65: -3451 | D65: Tata Motors FY26 Annual Report p.268 | E65: Source-derived | F65: Investing
A66: Net borrowings | B66: -6964 | C66: -4339 | D66: Tata Motors FY26 Annual Report p.269 | E66: Source-derived | F66: Financing
A67: Interest paid | B67: -1006 | C67: -884 | D67: Tata Motors FY26 Annual Report p.269 | E67: Source-derived | F67: Financing
A68: Net cash from financing activities | B68: -7970 | C68: -5223 | D68: Tata Motors FY26 Annual Report p.269 | E68: Source-derived | F68: Financing
...

Sheet Worked Examples
A1: WORKED EXAMPLES — INVESTMENT BANKING MODEL CALCULATIONS
A3: Calculation | B3: Formula / Logic | C3: Inputs | D3: Worked Result | E3: Purpose | F3: Evidence / Source
A4: FY26 Revenue Growth | B4: (FY26 Revenue / FY25 Revenue) - 1 | C4: 83,855 / 58,217 | D4: =Historical!C4/Historical!B4-1 -> 0.44038683 | E4: Demonstrates historical growth anchor | F4: Tata Motors FY26 P&L
A5: FY26 EBITDA | B5: Revenue × EBITDA Margin | C5: 83,855 × 12.3% | D5: =Historical!C4*12.3% -> 10314.165 | E5: Operating profit bridge | F5: FY26 disclosed underlying EBITDA margin 12.3%
A6: Acquisition Debt Funding | B6: Purchase Price × Debt % | C6: 41,691 × 80% | D6: =Assumptions!E29*Assumptions!C34 -> 33352.8 | E6: Sources of funds | F6: Assumptions sheet
A7: Acquisition Equity Funding | B7: Purchase Price × Equity % | C7: 41,691 × 10% | D7: =Assumptions!E29*Assumptions!D34 -> 4169.1 | E7: Sources of funds | F7: Assumptions sheet
A8: Acquisition Cash Funding | B8: Purchase Price × Cash % | C8: 41,691 × 10% | D8: =Assumptions!E29*Assumptions!B34 -> 4169.1 | E8: Sources of funds | F8: Assumptions sheet
A9: FY27 Iveco Revenue Contribution | B9: Iveco FY25 Revenue × (1+growth) × contribution factor | C9: 134,000 × 1.03 × 75% | D9: =Assumptions!E15*(1+Assumptions!E16)*Assumptions!E21 -> 103515 | E9: Partial-year contribution | F9: Source + assumption
A10: FY27 Synergy | B10: Annual synergy run-rate × FY27 ramp | C10: 1,500 × 25% | D10: =Assumptions!E22*Assumptions!E23 -> 375 | E10: Synergy realization | F10: Assumptions sheet
A11: FY27 New Debt Interest | B11: Acquisition debt × interest rate | C11: 33,352.8 × 7.5% | D11: =Assumptions!E29*Assumptions!C34*Assumptions!E34 -> 2501.46 | E11: Financing drag | F11: Assumptions sheet
A12: FY27 Post-tax Synergy | B12: Pre-tax synergy × (1-tax rate) | C12: 375 × (1-25%) | D12: =D10*(1-Assumptions!E6) -> 281.25 | E12: Bottom-line synergy | F12: Assumptions sheet
A13: Year-3 Net M&A Pre-tax Impact | B13: Iveco EBIT + Synergy - Integration Cost - Interest | C13: 6,901 + 750 - 100 - 1,876.1 | D13: ='M&A Model'!D14+'M&A Model'!D15-'M&A Model'!D16-'M&A Model'!D10 -> 5881.935 | E13: Deal contribution | F13: M&A Model
A14: FY27 Sources = Uses | B14: Cash + Debt + Equity - Purchase Price | C14: 4,169.1 + 33,352.8 + 4,169.1 - 41,691 | D14: ='M&A Model'!C5+'M&A Model'!C6+'M&A Model'!C7-'M&A Model'!C4 -> 0 | E14: Transaction integrity check | F14: M&A Model
A17: FINANCING SCENARIO COMPARISON — CONCRETE EVIDENCE
A19: Scenario | B19: Cash % | C19: Debt % | D19: Equity % | E19: New Debt (₹ cr) | F19: FY27 Interest (₹ cr)
A20: All Cash | B20: 1 | C20: 0 | D20: 0 | E20: =Assumptions!E29*B20 -> 41691 | F20: =E20*Assumptions!E33 -> 3126.825
A21: Balanced | B21: 0.1 | C21: 0.8 | D21: 0.1 | E21: =Assumptions!E29*C21 -> 33352.8 | F21: =E21*Assumptions!E34 -> 2501.46
A22: Debt Heavy | B22: 0.05 | C22: 0.9 | D22: 0.05 | E22: =Assumptions!E29*C22 -> 37521.9 | F22: =E22*Assumptions!E35 -> 3001.752
A25: YEAR-3 M&A SENSITIVITY — PRE-TAX DEAL IMPACT (₹ crore)
A27: Synergy / Purchase Price | B27: ₹38,000 cr | C27: ₹41,691 cr | D27: ₹45,000 cr
A28: ₹750 cr | B28: =7108.03+750-(38000*0.8*0.075)-100 -> 5478.03 | C28: =7108.03+750-(41691*0.8*0.075)-100 -> 5256.57 | D28: =7108.03+750-(45000*0.8*0.075)-100 -> 5058.03 | E28: Interest uses 80% debt at 7.5% | F28: Integration cost ₹100 cr | G28: Target EBIT held at base-case FY28E
A29: ₹1,500 cr | B29: =7108.03+1500-(38000*0.8*0.075)-100 -> 6228.03 | C29: =7108.03+1500-(41691*0.8*0.075)-100 -> 6006.57 | D29: =7108.03+1500-(45000*0.8*0.075)-100 -> 5808.03 | F29: Approximate model sensitivity
A30: ₹2,000 cr | B30: =7108.03+2000-(38000*0.8*0.075)-100 -> 6728.03 | C30: =7108.03+2000-(41691*0.8*0.075)-100 -> 6506.57 | D30: =7108.03+2000-(45000*0.8*0.075)-100 -> 6308.03 | F30: Higher synergy case
A31: Interpretation | E31: More negative = higher financing drag | F31: Higher = stronger synergy realization

Sheet Model Checks
A1: MODEL INTEGRITY CHECKS & EVIDENCE
A3: Check | B3: Formula | C3: Expected | D3: Actual | E3: Status
A4: FY26 Total Revenue | B4: Historical FY26 Revenue | C4: 83,855 | D4: =Historical!C4 -> 83855 | E4: =IF(D4=83855,"PASS","CHECK") -> PASS
A5: FY26 Total Assets | B5: Historical FY26 Total Assets | C5: 52,309 | D5: =Historical!C44 -> 52309 | E5: =IF(D5=52309,"PASS","CHECK") -> PASS
A6: FY26 Cash Flow | B6: Historical FY26 CFO | C6: 14,981 | D6: =Historical!C60 -> 14981 | E6: =IF(D6=14981,"PASS","CHECK") -> PASS
A7: FY27 Sources = Uses | B7: Debt + Equity + Cash - Purchase Price | C7: 0 | D7: ='M&A Model'!C5+'M&A Model'!C6+'M&A Model'!C7-'M&A Model'!C4 -> 0 | E7: =IF(ABS(D7)<0.1,"PASS","CHECK") -> PASS
A8: FY27 Forecast BS Balance | B8: Assets - Liabilities - Equity | C8: 0 | D8: ='Forecast BS'!C20 -> 0 | E8: =IF(ABS(D8)<0.1,"PASS","CHECK") -> PASS
A9: FY27 Ending Cash | B9: Beginning cash + net change | C9: Calculated | D9: ='Forecast CF'!C19 -> -4423.2901 | E9: =IF(D9='Forecast BS'!C9,"PASS","CHECK") -> PASS
A10: FY30 Debt Paydown | B10: M&A debt after 3 annual paydown steps | C10: < FY27 | D10: ='M&A Model'!F8 -> 14070.713 | E10: =IF(D10<'M&A Model'!C8,"PASS","CHECK") -> PASS
A11: Minimum cash test | B11: FY27 ending cash vs minimum cash | C11: ≥ minimum cash | D11: ='Forecast CF'!C19 -> -4423.2901 | E11: =IF(D11>=Assumptions!E11,"PASS","FUNDING NEEDED") -> FUNDING NEEDED
A12: Funding gap | B12: Minimum cash - FY27 ending cash (floor at zero) | C12: 0 if no gap; positive = funding needed | D12: ='M&A Model'!C22 -> 8423.2901 | E12: =IF(D12=0,"PASS","ACTION") -> ACTION

Sheet Limitations & Actions
A1: LIMITATIONS, MANAGEMENT QUESTIONS & ACTIONABLE NEXT STEPS
A3: Area | B3: Current limitation | C3: Evidence | D3: Impact on model | E3: Actionable next step | F3: Owner / Timing
A4: Tata Motors FY25 comparability | B4: FY25 comparative cash flow is a 9-month period and is not directly comparable to FY26 full-year cash flow. | C4: Annual report cash-flow note | D4: Historical growth rates can be misleading | E4: Use FY26 as the main forecast base; avoid annualising FY25 cash flow without adjustment. | F4: Analyst / Immediate
A5: Iveco operating financials | B5: The uploaded report discloses Iveco 2025 revenue and transaction value, but not a complete forecast P&L. | C5: Annual report Board’s Report / Chairman’s Message | D5: Target margins and earnings contribution are assumption-driven | E5: Replace assumed EBITDA/D&A/tax rates with confirmed deal-model disclosures when available. | F5: Deal team / At signing
A6: Purchase accounting | B6: ₹41,691 crore is equity consideration; purchase accounting / goodwill and fair-value step-ups are not yet fully modeled. | C6: Annual report transaction disclosure | D6: Can affect depreciation, amortisation, deferred taxes and equity. | E6: Add a purchase price allocation schedule once diligence data are available. | F6: Valuation / Closing
A7: Synergies | B7: Synergy run-rate is a management-style modeling assumption, not a disclosed commitment. | C7: Assumptions sheet | D7: Overstatement would inflate accretion. | E7: Build a synergy tracker by procurement, SG&A, logistics and cross-sell with named owners and timing. | F7: PMI / Monthly
A8: Financing | B8: Balanced case assumes 80% debt / 10% equity / 10% cash. | C8: Assumptions sheet | D8: Interest expense and leverage depend heavily on the mix. | E8: Run covenant, rating and interest-rate sensitivity before funding decision. | F8: Treasury / Pre-close
A9: Working capital | B9: Forecast uses a simplified revenue-based NWC driver. | C9: Forecast BS / CF | D9: Could miss target-specific seasonality and integration effects. | E9: Replace with DSO/DIO/DPO drivers from diligence and monthly operating data. | F9: FP&A / Pre-close
A10: FX | B10: Iveco revenue is translated from € to ₹ using a model assumption. | C10: Raw Data transaction evidence | D10: FX can materially change translated revenue and leverage metrics. | E10: Add EUR/INR sensitivity ±10% and hedge policy assumptions. | F10: Treasury / Quarterly
A11: Integration execution | B11: System, culture, customer retention and supply-chain risks are not captured directly in the financial forecast. | C11: PMI section / analyst judgment | D11: Execution failure can delay synergies or create one-time costs. | E11: Track Day-1, 100-day and 12-month milestones with KPI ownership. | F11: PMI / Weekly
A12: Liquidity in Balanced Case | B12: FY27 ending cash is below the ₹4,000 cr minimum cash assumption. | C12: Forecast CF / M&A funding | D12: Balance-sheet flexibility is constrained immediately after closing. | E12: Increase equity/cash funding, negotiate longer debt tenor, or add a committed revolving liquidity facility before close. | F12: Treasury / Pre-close
A13: Recommendation under current assumptions | B13: Do not rely on the balanced case without a funding bridge. | C13: Model Checks funding gap | D13: Model currently indicates incremental liquidity need. | E13: Prefer a financing mix that keeps minimum cash above ₹4,000 cr and stress-test 2.0% higher interest rates plus 10% lower synergies. | F13: Management / Investment Committee
